[2023-12-05 23:30:56 +0000] [12593] [INFO] Starting gunicorn 21.2.0
[2023-12-05 23:30:56 +0000] [12593] [INFO] Listening at: http://0.0.0.0:8000 (12593)
[2023-12-05 23:30:56 +0000] [12593] [INFO] Using worker: uvicorn.workers.UvicornWorker
[2023-12-05 23:30:56 +0000] [12595] [INFO] Booting worker with pid: 12595
[2023-12-05 23:30:56 +0000] [12596] [INFO] Booting worker with pid: 12596
[2023-12-05 23:30:56 +0000] [12597] [INFO] Booting worker with pid: 12597
[2023-12-05 23:30:56 +0000] [12598] [INFO] Booting worker with pid: 12598
[2023-12-05 23:30:58 +0000] [12595] [INFO] Started server process [12595]
[2023-12-05 23:30:58 +0000] [12595] [INFO] Waiting for application startup.
[2023-12-05 23:30:58 +0000] [12595] [INFO] Application startup complete.
[2023-12-05 23:30:58 +0000] [12596] [INFO] Started server process [12596]
[2023-12-05 23:30:58 +0000] [12596] [INFO] Waiting for application startup.
[2023-12-05 23:30:58 +0000] [12596] [INFO] Application startup complete.
[2023-12-05 23:30:58 +0000] [12597] [INFO] Started server process [12597]
[2023-12-05 23:30:58 +0000] [12597] [INFO] Waiting for application startup.
[2023-12-05 23:30:58 +0000] [12597] [INFO] Application startup complete.
[2023-12-05 23:30:58 +0000] [12598] [INFO] Started server process [12598]
[2023-12-05 23:30:58 +0000] [12598] [INFO] Waiting for application startup.
[2023-12-05 23:30:58 +0000] [12598] [INFO] Application startup complete.
[2023-12-05 23:34:37 +0000] [12593] [INFO] Handling signal: hup
[2023-12-05 23:34:37 +0000] [12593] [INFO] Hang up: Master
[2023-12-05 23:34:37 +0000] [12714] [INFO] Booting worker with pid: 12714
[2023-12-05 23:34:37 +0000] [12593] [ERROR] Worker (pid:12595) was sent SIGHUP!
[2023-12-05 23:34:37 +0000] [12593] [ERROR] Worker (pid:12596) was sent SIGHUP!
[2023-12-05 23:34:37 +0000] [12715] [INFO] Booting worker with pid: 12715
[2023-12-05 23:34:37 +0000] [12593] [ERROR] Worker (pid:12598) was sent SIGHUP!
[2023-12-05 23:34:37 +0000] [12716] [INFO] Booting worker with pid: 12716
[2023-12-05 23:34:37 +0000] [12593] [ERROR] Worker (pid:12597) was sent SIGHUP!
[2023-12-05 23:34:37 +0000] [12717] [INFO] Booting worker with pid: 12717
[2023-12-05 23:34:39 +0000] [12714] [INFO] Started server process [12714]
[2023-12-05 23:34:39 +0000] [12714] [INFO] Waiting for application startup.
[2023-12-05 23:34:39 +0000] [12714] [INFO] Application startup complete.
[2023-12-05 23:34:39 +0000] [12717] [INFO] Started server process [12717]
[2023-12-05 23:34:39 +0000] [12717] [INFO] Waiting for application startup.
[2023-12-05 23:34:39 +0000] [12717] [INFO] Application startup complete.
[2023-12-05 23:34:39 +0000] [12716] [INFO] Started server process [12716]
[2023-12-05 23:34:39 +0000] [12716] [INFO] Waiting for application startup.
[2023-12-05 23:34:39 +0000] [12716] [INFO] Application startup complete.
[2023-12-05 23:34:39 +0000] [12715] [INFO] Started server process [12715]
[2023-12-05 23:34:39 +0000] [12715] [INFO] Waiting for application startup.
[2023-12-05 23:34:39 +0000] [12715] [INFO] Application startup complete.
[2023-12-06 02:26:34 +0000] [12715] [WARNING] Invalid HTTP request received.
[2023-12-06 02:26:34 +0000] [12716] [WARNING] Invalid HTTP request received.
[2023-12-06 02:26:34 +0000] [12716] [WARNING] Invalid HTTP request received.
[2023-12-06 02:26:34 +0000] [12715] [WARNING] Invalid HTTP request received.
[2023-12-06 02:26:34 +0000] [12715] [WARNING] Invalid HTTP request received.
[2023-12-06 02:26:34 +0000] [12715] [WARNING] Invalid HTTP request received.
[2023-12-06 02:26:34 +0000] [12716] [WARNING] Invalid HTTP request received.
[2023-12-06 02:26:34 +0000] [12715] [WARNING] Invalid HTTP request received.
[2023-12-06 02:26:34 +0000] [12715] [WARNING] Invalid HTTP request received.
[2023-12-06 03:18:04 +0000] [12717] [WARNING] Unsupported upgrade request.
[2023-12-06 03:18:04 +0000] [12717] [WARNING] No supported WebSocket library detected. Please use "pip install 'uvicorn[standard]'", or install 'websockets' or 'wsproto' manually.
[2023-12-06 03:18:04 +0000] [12717] [WARNING] Invalid HTTP request received.
[2023-12-06 09:04:48 +0000] [12714] [WARNING] Invalid HTTP request received.
[2023-12-06 09:32:17 +0000] [12716] [WARNING] Invalid HTTP request received.
[2023-12-06 10:41:41 +0000] [12715] [WARNING] Invalid HTTP request received.
[2023-12-06 11:37:14 +0000] [12714] [WARNING] Invalid HTTP request received.
[2023-12-06 13:17:27 +0000] [12715] [WARNING] Invalid HTTP request received.
[2023-12-06 19:22:38 +0000] [12715] [WARNING] Invalid HTTP request received.
[2023-12-06 19:24:56 +0000] [12717] [WARNING] Invalid HTTP request received.
[2023-12-06 19:24:56 +0000] [12717] [WARNING] Invalid HTTP request received.
[2023-12-06 19:24:56 +0000] [12715] [WARNING] Invalid HTTP request received.
[2023-12-06 19:27:30 +0000] [12715] [WARNING] Invalid HTTP request received.
[2023-12-06 19:27:34 +0000] [12716] [WARNING] Invalid HTTP request received.
[2023-12-06 19:27:35 +0000] [12716] [WARNING] Invalid HTTP request received.
[2023-12-06 19:27:36 +0000] [12715] [WARNING] Invalid HTTP request received.
[2023-12-06 19:27:37 +0000] [12716] [WARNING] Invalid HTTP request received.
[2023-12-06 19:27:37 +0000] [12715] [WARNING] Invalid HTTP request received.
[2023-12-06 19:27:38 +0000] [12716] [WARNING] Invalid HTTP request received.
[2023-12-06 21:58:34 +0000] [12717] [WARNING] Invalid HTTP request received.
[2023-12-06 21:58:34 +0000] [12717] [WARNING] Invalid HTTP request received.
[2023-12-07 01:28:27 +0000] [12715] [WARNING] Invalid HTTP request received.
[2023-12-07 01:36:29 +0000] [12715] [WARNING] Invalid HTTP request received.
[2023-12-07 02:46:55 +0000] [12716] [WARNING] Invalid HTTP request received.
[2023-12-07 06:08:11 +0000] [12717] [WARNING] Unsupported upgrade request.
[2023-12-07 06:08:11 +0000] [12717] [WARNING] No supported WebSocket library detected. Please use "pip install 'uvicorn[standard]'", or install 'websockets' or 'wsproto' manually.
[2023-12-07 06:08:11 +0000] [12717] [WARNING] Invalid HTTP request received.
[2023-12-07 07:14:00 +0000] [12714] [WARNING] Invalid HTTP request received.
[2023-12-07 07:14:00 +0000] [12715] [WARNING] Invalid HTTP request received.
[2023-12-07 07:14:00 +0000] [12715] [WARNING] Invalid HTTP request received.
[2023-12-07 11:39:40 +0000] [12717] [WARNING] Invalid HTTP request received.
[2023-12-07 13:49:03 +0000] [12717] [WARNING] Invalid HTTP request received.
[2023-12-07 13:49:03 +0000] [12715] [WARNING] Invalid HTTP request received.
[2023-12-07 13:49:03 +0000] [12715] [WARNING] Invalid HTTP request received.
[2023-12-07 13:49:03 +0000] [12715] [WARNING] Invalid HTTP request received.
[2023-12-07 13:49:03 +0000] [12716] [WARNING] Invalid HTTP request received.
[2023-12-07 13:49:03 +0000] [12715] [WARNING] Invalid HTTP request received.
[2023-12-07 15:29:44 +0000] [35189] [INFO] Starting gunicorn 21.2.0
[2023-12-07 15:29:44 +0000] [35189] [ERROR] Connection in use: ('0.0.0.0', 8000)
[2023-12-07 15:29:44 +0000] [35189] [ERROR] Retrying in 1 second.
[2023-12-07 15:29:45 +0000] [35189] [ERROR] Connection in use: ('0.0.0.0', 8000)
[2023-12-07 15:29:45 +0000] [35189] [ERROR] Retrying in 1 second.
[2023-12-07 15:29:46 +0000] [35189] [ERROR] Connection in use: ('0.0.0.0', 8000)
[2023-12-07 15:29:46 +0000] [35189] [ERROR] Retrying in 1 second.
[2023-12-07 15:29:47 +0000] [35189] [ERROR] Connection in use: ('0.0.0.0', 8000)
[2023-12-07 15:29:47 +0000] [35189] [ERROR] Retrying in 1 second.
[2023-12-07 15:29:48 +0000] [35189] [ERROR] Connection in use: ('0.0.0.0', 8000)
[2023-12-07 15:29:48 +0000] [35189] [ERROR] Retrying in 1 second.
[2023-12-07 15:29:49 +0000] [35189] [ERROR] Can't connect to ('0.0.0.0', 8000)
[2023-12-07 15:43:25 +0000] [12716] [ERROR] Exception in ASGI application
Traceback (most recent call last):
  File "/home/azureuser/DeepVoice-English-API/venv/lib/python3.8/site-packages/uvicorn/protocols/http/httptools_impl.py", line 426, in run_asgi
    result = await app(  # type: ignore[func-returns-value]
  File "/home/azureuser/DeepVoice-English-API/venv/lib/python3.8/site-packages/uvicorn/middleware/proxy_headers.py", line 84, in __call__
    return await self.app(scope, receive, send)
  File "/home/azureuser/DeepVoice-English-API/venv/lib/python3.8/site-packages/fastapi/applications.py", line 292, in __call__
    await super().__call__(scope, receive, send)
  File "/home/azureuser/DeepVoice-English-API/venv/lib/python3.8/site-packages/starlette/applications.py", line 122, in __call__
    await self.middleware_stack(scope, receive, send)
  File "/home/azureuser/DeepVoice-English-API/venv/lib/python3.8/site-packages/starlette/middleware/errors.py", line 184, in __call__
    raise exc
  File "/home/azureuser/DeepVoice-English-API/venv/lib/python3.8/site-packages/starlette/middleware/errors.py", line 162, in __call__
    await self.app(scope, receive, _send)
  File "/home/azureuser/DeepVoice-English-API/venv/lib/python3.8/site-packages/starlette/middleware/cors.py", line 91, in __call__
    await self.simple_response(scope, receive, send, request_headers=headers)
  File "/home/azureuser/DeepVoice-English-API/venv/lib/python3.8/site-packages/starlette/middleware/cors.py", line 146, in simple_response
    await self.app(scope, receive, send)
  File "/home/azureuser/DeepVoice-English-API/venv/lib/python3.8/site-packages/starlette/middleware/exceptions.py", line 79, in __call__
    raise exc
  File "/home/azureuser/DeepVoice-English-API/venv/lib/python3.8/site-packages/starlette/middleware/exceptions.py", line 68, in __call__
    await self.app(scope, receive, sender)
  File "/home/azureuser/DeepVoice-English-API/venv/lib/python3.8/site-packages/fastapi/middleware/asyncexitstack.py", line 20, in __call__
    raise e
  File "/home/azureuser/DeepVoice-English-API/venv/lib/python3.8/site-packages/fastapi/middleware/asyncexitstack.py", line 17, in __call__
    await self.app(scope, receive, send)
  File "/home/azureuser/DeepVoice-English-API/venv/lib/python3.8/site-packages/starlette/routing.py", line 718, in __call__
    await route.handle(scope, receive, send)
  File "/home/azureuser/DeepVoice-English-API/venv/lib/python3.8/site-packages/starlette/routing.py", line 276, in handle
    await self.app(scope, receive, send)
  File "/home/azureuser/DeepVoice-English-API/venv/lib/python3.8/site-packages/starlette/routing.py", line 66, in app
    response = await func(request)
  File "/home/azureuser/DeepVoice-English-API/venv/lib/python3.8/site-packages/fastapi/routing.py", line 273, in app
    raw_response = await run_endpoint_function(
  File "/home/azureuser/DeepVoice-English-API/venv/lib/python3.8/site-packages/fastapi/routing.py", line 192, in run_endpoint_function
    return await run_in_threadpool(dependant.call, **values)
  File "/home/azureuser/DeepVoice-English-API/venv/lib/python3.8/site-packages/starlette/concurrency.py", line 41, in run_in_threadpool
    return await anyio.to_thread.run_sync(func, *args)
  File "/home/azureuser/DeepVoice-English-API/venv/lib/python3.8/site-packages/anyio/to_thread.py", line 33, in run_sync
    return await get_asynclib().run_sync_in_worker_thread(
  File "/home/azureuser/DeepVoice-English-API/venv/lib/python3.8/site-packages/anyio/_backends/_asyncio.py", line 877, in run_sync_in_worker_thread
    return await future
  File "/home/azureuser/DeepVoice-English-API/venv/lib/python3.8/site-packages/anyio/_backends/_asyncio.py", line 807, in run
    result = context.run(func, *args)
  File "/home/azureuser/DeepVoice-English-API/app/company/companyController.py", line 23, in create_company
    fernet = Fernet(os.getenv("UID_KEY"))
  File "/home/azureuser/DeepVoice-English-API/venv/lib/python3.8/site-packages/cryptography/fernet.py", line 34, in __init__
    key = base64.urlsafe_b64decode(key)
  File "/usr/lib/python3.8/base64.py", line 131, in urlsafe_b64decode
    s = _bytes_from_decode_data(s)
  File "/usr/lib/python3.8/base64.py", line 45, in _bytes_from_decode_data
    raise TypeError("argument should be a bytes-like object or ASCII "
TypeError: argument should be a bytes-like object or ASCII string, not 'NoneType'
[2023-12-07 15:49:30 +0000] [35537] [INFO] Starting gunicorn 21.2.0
[2023-12-07 15:49:30 +0000] [35537] [ERROR] Connection in use: ('0.0.0.0', 8000)
[2023-12-07 15:49:30 +0000] [35537] [ERROR] Retrying in 1 second.
[2023-12-07 15:49:31 +0000] [35537] [ERROR] Connection in use: ('0.0.0.0', 8000)
[2023-12-07 15:49:31 +0000] [35537] [ERROR] Retrying in 1 second.
[2023-12-07 15:49:32 +0000] [35537] [ERROR] Connection in use: ('0.0.0.0', 8000)
[2023-12-07 15:49:32 +0000] [35537] [ERROR] Retrying in 1 second.
[2023-12-07 15:49:33 +0000] [35537] [ERROR] Connection in use: ('0.0.0.0', 8000)
[2023-12-07 15:49:33 +0000] [35537] [ERROR] Retrying in 1 second.
[2023-12-07 15:49:34 +0000] [35537] [ERROR] Connection in use: ('0.0.0.0', 8000)
[2023-12-07 15:49:34 +0000] [35537] [ERROR] Retrying in 1 second.
[2023-12-07 15:49:35 +0000] [35537] [ERROR] Can't connect to ('0.0.0.0', 8000)
[2023-12-07 15:50:05 +0000] [12716] [ERROR] Exception in ASGI application
Traceback (most recent call last):
  File "/home/azureuser/DeepVoice-English-API/venv/lib/python3.8/site-packages/uvicorn/protocols/http/httptools_impl.py", line 426, in run_asgi
    result = await app(  # type: ignore[func-returns-value]
  File "/home/azureuser/DeepVoice-English-API/venv/lib/python3.8/site-packages/uvicorn/middleware/proxy_headers.py", line 84, in __call__
    return await self.app(scope, receive, send)
  File "/home/azureuser/DeepVoice-English-API/venv/lib/python3.8/site-packages/fastapi/applications.py", line 292, in __call__
    await super().__call__(scope, receive, send)
  File "/home/azureuser/DeepVoice-English-API/venv/lib/python3.8/site-packages/starlette/applications.py", line 122, in __call__
    await self.middleware_stack(scope, receive, send)
  File "/home/azureuser/DeepVoice-English-API/venv/lib/python3.8/site-packages/starlette/middleware/errors.py", line 184, in __call__
    raise exc
  File "/home/azureuser/DeepVoice-English-API/venv/lib/python3.8/site-packages/starlette/middleware/errors.py", line 162, in __call__
    await self.app(scope, receive, _send)
  File "/home/azureuser/DeepVoice-English-API/venv/lib/python3.8/site-packages/starlette/middleware/cors.py", line 91, in __call__
    await self.simple_response(scope, receive, send, request_headers=headers)
  File "/home/azureuser/DeepVoice-English-API/venv/lib/python3.8/site-packages/starlette/middleware/cors.py", line 146, in simple_response
    await self.app(scope, receive, send)
  File "/home/azureuser/DeepVoice-English-API/venv/lib/python3.8/site-packages/starlette/middleware/exceptions.py", line 79, in __call__
    raise exc
  File "/home/azureuser/DeepVoice-English-API/venv/lib/python3.8/site-packages/starlette/middleware/exceptions.py", line 68, in __call__
    await self.app(scope, receive, sender)
  File "/home/azureuser/DeepVoice-English-API/venv/lib/python3.8/site-packages/fastapi/middleware/asyncexitstack.py", line 20, in __call__
    raise e
  File "/home/azureuser/DeepVoice-English-API/venv/lib/python3.8/site-packages/fastapi/middleware/asyncexitstack.py", line 17, in __call__
    await self.app(scope, receive, send)
  File "/home/azureuser/DeepVoice-English-API/venv/lib/python3.8/site-packages/starlette/routing.py", line 718, in __call__
    await route.handle(scope, receive, send)
  File "/home/azureuser/DeepVoice-English-API/venv/lib/python3.8/site-packages/starlette/routing.py", line 276, in handle
    await self.app(scope, receive, send)
  File "/home/azureuser/DeepVoice-English-API/venv/lib/python3.8/site-packages/starlette/routing.py", line 66, in app
    response = await func(request)
  File "/home/azureuser/DeepVoice-English-API/venv/lib/python3.8/site-packages/fastapi/routing.py", line 273, in app
    raw_response = await run_endpoint_function(
  File "/home/azureuser/DeepVoice-English-API/venv/lib/python3.8/site-packages/fastapi/routing.py", line 192, in run_endpoint_function
    return await run_in_threadpool(dependant.call, **values)
  File "/home/azureuser/DeepVoice-English-API/venv/lib/python3.8/site-packages/starlette/concurrency.py", line 41, in run_in_threadpool
    return await anyio.to_thread.run_sync(func, *args)
  File "/home/azureuser/DeepVoice-English-API/venv/lib/python3.8/site-packages/anyio/to_thread.py", line 33, in run_sync
    return await get_asynclib().run_sync_in_worker_thread(
  File "/home/azureuser/DeepVoice-English-API/venv/lib/python3.8/site-packages/anyio/_backends/_asyncio.py", line 877, in run_sync_in_worker_thread
    return await future
  File "/home/azureuser/DeepVoice-English-API/venv/lib/python3.8/site-packages/anyio/_backends/_asyncio.py", line 807, in run
    result = context.run(func, *args)
  File "/home/azureuser/DeepVoice-English-API/app/company/companyController.py", line 23, in create_company
    fernet = Fernet(os.getenv("UID_KEY"))
  File "/home/azureuser/DeepVoice-English-API/venv/lib/python3.8/site-packages/cryptography/fernet.py", line 34, in __init__
    key = base64.urlsafe_b64decode(key)
  File "/usr/lib/python3.8/base64.py", line 131, in urlsafe_b64decode
    s = _bytes_from_decode_data(s)
  File "/usr/lib/python3.8/base64.py", line 45, in _bytes_from_decode_data
    raise TypeError("argument should be a bytes-like object or ASCII "
TypeError: argument should be a bytes-like object or ASCII string, not 'NoneType'
[2023-12-07 15:50:34 +0000] [12714] [ERROR] Exception in ASGI application
Traceback (most recent call last):
  File "/home/azureuser/DeepVoice-English-API/venv/lib/python3.8/site-packages/sqlalchemy/engine/base.py", line 145, in __init__
    self._dbapi_connection = engine.raw_connection()
  File "/home/azureuser/DeepVoice-English-API/venv/lib/python3.8/site-packages/sqlalchemy/engine/base.py", line 3292, in raw_connection
    return self.pool.connect()
  File "/home/azureuser/DeepVoice-English-API/venv/lib/python3.8/site-packages/sqlalchemy/pool/base.py", line 452, in connect
    return _ConnectionFairy._checkout(self)
  File "/home/azureuser/DeepVoice-English-API/venv/lib/python3.8/site-packages/sqlalchemy/pool/base.py", line 1269, in _checkout
    fairy = _ConnectionRecord.checkout(pool)
  File "/home/azureuser/DeepVoice-English-API/venv/lib/python3.8/site-packages/sqlalchemy/pool/base.py", line 716, in checkout
    rec = pool._do_get()
  File "/home/azureuser/DeepVoice-English-API/venv/lib/python3.8/site-packages/sqlalchemy/pool/impl.py", line 170, in _do_get
    self._dec_overflow()
  File "/home/azureuser/DeepVoice-English-API/venv/lib/python3.8/site-packages/sqlalchemy/util/langhelpers.py", line 146, in __exit__
    raise exc_value.with_traceback(exc_tb)
  File "/home/azureuser/DeepVoice-English-API/venv/lib/python3.8/site-packages/sqlalchemy/pool/impl.py", line 167, in _do_get
    return self._create_connection()
  File "/home/azureuser/DeepVoice-English-API/venv/lib/python3.8/site-packages/sqlalchemy/pool/base.py", line 393, in _create_connection
    return _ConnectionRecord(self)
  File "/home/azureuser/DeepVoice-English-API/venv/lib/python3.8/site-packages/sqlalchemy/pool/base.py", line 678, in __init__
    self.__connect()
  File "/home/azureuser/DeepVoice-English-API/venv/lib/python3.8/site-packages/sqlalchemy/pool/base.py", line 903, in __connect
    pool.logger.debug("Error on connect(): %s", e)
  File "/home/azureuser/DeepVoice-English-API/venv/lib/python3.8/site-packages/sqlalchemy/util/langhelpers.py", line 146, in __exit__
    raise exc_value.with_traceback(exc_tb)
  File "/home/azureuser/DeepVoice-English-API/venv/lib/python3.8/site-packages/sqlalchemy/pool/base.py", line 898, in __connect
    self.dbapi_connection = connection = pool._invoke_creator(self)
  File "/home/azureuser/DeepVoice-English-API/venv/lib/python3.8/site-packages/sqlalchemy/engine/create.py", line 637, in connect
    return dialect.connect(*cargs, **cparams)
  File "/home/azureuser/DeepVoice-English-API/venv/lib/python3.8/site-packages/sqlalchemy/engine/default.py", line 616, in connect
    return self.loaded_dbapi.connect(*cargs, **cparams)
  File "/home/azureuser/DeepVoice-English-API/venv/lib/python3.8/site-packages/psycopg2/__init__.py", line 122, in connect
    conn = _connect(dsn, connection_factory=connection_factory, **kwasync)
psycopg2.OperationalError: could not translate host name "none" to address: Temporary failure in name resolution


The above exception was the direct cause of the following exception:

Traceback (most recent call last):
  File "/home/azureuser/DeepVoice-English-API/venv/lib/python3.8/site-packages/uvicorn/protocols/http/httptools_impl.py", line 426, in run_asgi
    result = await app(  # type: ignore[func-returns-value]
  File "/home/azureuser/DeepVoice-English-API/venv/lib/python3.8/site-packages/uvicorn/middleware/proxy_headers.py", line 84, in __call__
    return await self.app(scope, receive, send)
  File "/home/azureuser/DeepVoice-English-API/venv/lib/python3.8/site-packages/fastapi/applications.py", line 292, in __call__
    await super().__call__(scope, receive, send)
  File "/home/azureuser/DeepVoice-English-API/venv/lib/python3.8/site-packages/starlette/applications.py", line 122, in __call__
    await self.middleware_stack(scope, receive, send)
  File "/home/azureuser/DeepVoice-English-API/venv/lib/python3.8/site-packages/starlette/middleware/errors.py", line 184, in __call__
    raise exc
  File "/home/azureuser/DeepVoice-English-API/venv/lib/python3.8/site-packages/starlette/middleware/errors.py", line 162, in __call__
    await self.app(scope, receive, _send)
  File "/home/azureuser/DeepVoice-English-API/venv/lib/python3.8/site-packages/starlette/middleware/cors.py", line 83, in __call__
    await self.app(scope, receive, send)
  File "/home/azureuser/DeepVoice-English-API/venv/lib/python3.8/site-packages/starlette/middleware/exceptions.py", line 79, in __call__
    raise exc
  File "/home/azureuser/DeepVoice-English-API/venv/lib/python3.8/site-packages/starlette/middleware/exceptions.py", line 68, in __call__
    await self.app(scope, receive, sender)
  File "/home/azureuser/DeepVoice-English-API/venv/lib/python3.8/site-packages/fastapi/middleware/asyncexitstack.py", line 20, in __call__
    raise e
  File "/home/azureuser/DeepVoice-English-API/venv/lib/python3.8/site-packages/fastapi/middleware/asyncexitstack.py", line 17, in __call__
    await self.app(scope, receive, send)
  File "/home/azureuser/DeepVoice-English-API/venv/lib/python3.8/site-packages/starlette/routing.py", line 718, in __call__
    await route.handle(scope, receive, send)
  File "/home/azureuser/DeepVoice-English-API/venv/lib/python3.8/site-packages/starlette/routing.py", line 276, in handle
    await self.app(scope, receive, send)
  File "/home/azureuser/DeepVoice-English-API/venv/lib/python3.8/site-packages/starlette/routing.py", line 66, in app
    response = await func(request)
  File "/home/azureuser/DeepVoice-English-API/venv/lib/python3.8/site-packages/fastapi/routing.py", line 273, in app
    raw_response = await run_endpoint_function(
  File "/home/azureuser/DeepVoice-English-API/venv/lib/python3.8/site-packages/fastapi/routing.py", line 192, in run_endpoint_function
    return await run_in_threadpool(dependant.call, **values)
  File "/home/azureuser/DeepVoice-English-API/venv/lib/python3.8/site-packages/starlette/concurrency.py", line 41, in run_in_threadpool
    return await anyio.to_thread.run_sync(func, *args)
  File "/home/azureuser/DeepVoice-English-API/venv/lib/python3.8/site-packages/anyio/to_thread.py", line 33, in run_sync
    return await get_asynclib().run_sync_in_worker_thread(
  File "/home/azureuser/DeepVoice-English-API/venv/lib/python3.8/site-packages/anyio/_backends/_asyncio.py", line 877, in run_sync_in_worker_thread
    return await future
  File "/home/azureuser/DeepVoice-English-API/venv/lib/python3.8/site-packages/anyio/_backends/_asyncio.py", line 807, in run
    result = context.run(func, *args)
  File "/home/azureuser/DeepVoice-English-API/app/company/companyController.py", line 35, in get_company
    currentCompany = company.get(db=db, id=company_id)
  File "/home/azureuser/DeepVoice-English-API/app/baseController.py", line 27, in get
    return db.query(self.model).filter(self.model.id == id).first()
  File "/home/azureuser/DeepVoice-English-API/venv/lib/python3.8/site-packages/sqlalchemy/orm/query.py", line 2748, in first
    return self.limit(1)._iter().first()  # type: ignore
  File "/home/azureuser/DeepVoice-English-API/venv/lib/python3.8/site-packages/sqlalchemy/orm/query.py", line 2847, in _iter
    result: Union[ScalarResult[_T], Result[_T]] = self.session.execute(
  File "/home/azureuser/DeepVoice-English-API/venv/lib/python3.8/site-packages/sqlalchemy/orm/session.py", line 2306, in execute
    return self._execute_internal(
  File "/home/azureuser/DeepVoice-English-API/venv/lib/python3.8/site-packages/sqlalchemy/orm/session.py", line 2178, in _execute_internal
    conn = self._connection_for_bind(bind)
  File "/home/azureuser/DeepVoice-English-API/venv/lib/python3.8/site-packages/sqlalchemy/orm/session.py", line 2045, in _connection_for_bind
    return trans._connection_for_bind(engine, execution_options)
  File "<string>", line 2, in _connection_for_bind
  File "/home/azureuser/DeepVoice-English-API/venv/lib/python3.8/site-packages/sqlalchemy/orm/state_changes.py", line 139, in _go
    ret_value = fn(self, *arg, **kw)
  File "/home/azureuser/DeepVoice-English-API/venv/lib/python3.8/site-packages/sqlalchemy/orm/session.py", line 1143, in _connection_for_bind
    conn = bind.connect()
  File "/home/azureuser/DeepVoice-English-API/venv/lib/python3.8/site-packages/sqlalchemy/engine/base.py", line 3268, in connect
    return self._connection_cls(self)
  File "/home/azureuser/DeepVoice-English-API/venv/lib/python3.8/site-packages/sqlalchemy/engine/base.py", line 147, in __init__
    Connection._handle_dbapi_exception_noconnection(
  File "/home/azureuser/DeepVoice-English-API/venv/lib/python3.8/site-packages/sqlalchemy/engine/base.py", line 2430, in _handle_dbapi_exception_noconnection
    raise sqlalchemy_exception.with_traceback(exc_info[2]) from e
  File "/home/azureuser/DeepVoice-English-API/venv/lib/python3.8/site-packages/sqlalchemy/engine/base.py", line 145, in __init__
    self._dbapi_connection = engine.raw_connection()
  File "/home/azureuser/DeepVoice-English-API/venv/lib/python3.8/site-packages/sqlalchemy/engine/base.py", line 3292, in raw_connection
    return self.pool.connect()
  File "/home/azureuser/DeepVoice-English-API/venv/lib/python3.8/site-packages/sqlalchemy/pool/base.py", line 452, in connect
    return _ConnectionFairy._checkout(self)
  File "/home/azureuser/DeepVoice-English-API/venv/lib/python3.8/site-packages/sqlalchemy/pool/base.py", line 1269, in _checkout
    fairy = _ConnectionRecord.checkout(pool)
  File "/home/azureuser/DeepVoice-English-API/venv/lib/python3.8/site-packages/sqlalchemy/pool/base.py", line 716, in checkout
    rec = pool._do_get()
  File "/home/azureuser/DeepVoice-English-API/venv/lib/python3.8/site-packages/sqlalchemy/pool/impl.py", line 170, in _do_get
    self._dec_overflow()
  File "/home/azureuser/DeepVoice-English-API/venv/lib/python3.8/site-packages/sqlalchemy/util/langhelpers.py", line 146, in __exit__
    raise exc_value.with_traceback(exc_tb)
  File "/home/azureuser/DeepVoice-English-API/venv/lib/python3.8/site-packages/sqlalchemy/pool/impl.py", line 167, in _do_get
    return self._create_connection()
  File "/home/azureuser/DeepVoice-English-API/venv/lib/python3.8/site-packages/sqlalchemy/pool/base.py", line 393, in _create_connection
    return _ConnectionRecord(self)
  File "/home/azureuser/DeepVoice-English-API/venv/lib/python3.8/site-packages/sqlalchemy/pool/base.py", line 678, in __init__
    self.__connect()
  File "/home/azureuser/DeepVoice-English-API/venv/lib/python3.8/site-packages/sqlalchemy/pool/base.py", line 903, in __connect
    pool.logger.debug("Error on connect(): %s", e)
  File "/home/azureuser/DeepVoice-English-API/venv/lib/python3.8/site-packages/sqlalchemy/util/langhelpers.py", line 146, in __exit__
    raise exc_value.with_traceback(exc_tb)
  File "/home/azureuser/DeepVoice-English-API/venv/lib/python3.8/site-packages/sqlalchemy/pool/base.py", line 898, in __connect
    self.dbapi_connection = connection = pool._invoke_creator(self)
  File "/home/azureuser/DeepVoice-English-API/venv/lib/python3.8/site-packages/sqlalchemy/engine/create.py", line 637, in connect
    return dialect.connect(*cargs, **cparams)
  File "/home/azureuser/DeepVoice-English-API/venv/lib/python3.8/site-packages/sqlalchemy/engine/default.py", line 616, in connect
    return self.loaded_dbapi.connect(*cargs, **cparams)
  File "/home/azureuser/DeepVoice-English-API/venv/lib/python3.8/site-packages/psycopg2/__init__.py", line 122, in connect
    conn = _connect(dsn, connection_factory=connection_factory, **kwasync)
sqlalchemy.exc.OperationalError: (psycopg2.OperationalError) could not translate host name "none" to address: Temporary failure in name resolution

(Background on this error at: https://sqlalche.me/e/20/e3q8)
[2023-12-07 15:50:35 +0000] [12716] [ERROR] Exception in ASGI application
Traceback (most recent call last):
  File "/home/azureuser/DeepVoice-English-API/venv/lib/python3.8/site-packages/sqlalchemy/engine/base.py", line 145, in __init__
    self._dbapi_connection = engine.raw_connection()
  File "/home/azureuser/DeepVoice-English-API/venv/lib/python3.8/site-packages/sqlalchemy/engine/base.py", line 3292, in raw_connection
    return self.pool.connect()
  File "/home/azureuser/DeepVoice-English-API/venv/lib/python3.8/site-packages/sqlalchemy/pool/base.py", line 452, in connect
    return _ConnectionFairy._checkout(self)
  File "/home/azureuser/DeepVoice-English-API/venv/lib/python3.8/site-packages/sqlalchemy/pool/base.py", line 1269, in _checkout
    fairy = _ConnectionRecord.checkout(pool)
  File "/home/azureuser/DeepVoice-English-API/venv/lib/python3.8/site-packages/sqlalchemy/pool/base.py", line 716, in checkout
    rec = pool._do_get()
  File "/home/azureuser/DeepVoice-English-API/venv/lib/python3.8/site-packages/sqlalchemy/pool/impl.py", line 170, in _do_get
    self._dec_overflow()
  File "/home/azureuser/DeepVoice-English-API/venv/lib/python3.8/site-packages/sqlalchemy/util/langhelpers.py", line 146, in __exit__
    raise exc_value.with_traceback(exc_tb)
  File "/home/azureuser/DeepVoice-English-API/venv/lib/python3.8/site-packages/sqlalchemy/pool/impl.py", line 167, in _do_get
    return self._create_connection()
  File "/home/azureuser/DeepVoice-English-API/venv/lib/python3.8/site-packages/sqlalchemy/pool/base.py", line 393, in _create_connection
    return _ConnectionRecord(self)
  File "/home/azureuser/DeepVoice-English-API/venv/lib/python3.8/site-packages/sqlalchemy/pool/base.py", line 678, in __init__
    self.__connect()
  File "/home/azureuser/DeepVoice-English-API/venv/lib/python3.8/site-packages/sqlalchemy/pool/base.py", line 903, in __connect
    pool.logger.debug("Error on connect(): %s", e)
  File "/home/azureuser/DeepVoice-English-API/venv/lib/python3.8/site-packages/sqlalchemy/util/langhelpers.py", line 146, in __exit__
    raise exc_value.with_traceback(exc_tb)
  File "/home/azureuser/DeepVoice-English-API/venv/lib/python3.8/site-packages/sqlalchemy/pool/base.py", line 898, in __connect
    self.dbapi_connection = connection = pool._invoke_creator(self)
  File "/home/azureuser/DeepVoice-English-API/venv/lib/python3.8/site-packages/sqlalchemy/engine/create.py", line 637, in connect
    return dialect.connect(*cargs, **cparams)
  File "/home/azureuser/DeepVoice-English-API/venv/lib/python3.8/site-packages/sqlalchemy/engine/default.py", line 616, in connect
    return self.loaded_dbapi.connect(*cargs, **cparams)
  File "/home/azureuser/DeepVoice-English-API/venv/lib/python3.8/site-packages/psycopg2/__init__.py", line 122, in connect
    conn = _connect(dsn, connection_factory=connection_factory, **kwasync)
psycopg2.OperationalError: could not translate host name "none" to address: Temporary failure in name resolution


The above exception was the direct cause of the following exception:

Traceback (most recent call last):
  File "/home/azureuser/DeepVoice-English-API/venv/lib/python3.8/site-packages/uvicorn/protocols/http/httptools_impl.py", line 426, in run_asgi
    result = await app(  # type: ignore[func-returns-value]
  File "/home/azureuser/DeepVoice-English-API/venv/lib/python3.8/site-packages/uvicorn/middleware/proxy_headers.py", line 84, in __call__
    return await self.app(scope, receive, send)
  File "/home/azureuser/DeepVoice-English-API/venv/lib/python3.8/site-packages/fastapi/applications.py", line 292, in __call__
    await super().__call__(scope, receive, send)
  File "/home/azureuser/DeepVoice-English-API/venv/lib/python3.8/site-packages/starlette/applications.py", line 122, in __call__
    await self.middleware_stack(scope, receive, send)
  File "/home/azureuser/DeepVoice-English-API/venv/lib/python3.8/site-packages/starlette/middleware/errors.py", line 184, in __call__
    raise exc
  File "/home/azureuser/DeepVoice-English-API/venv/lib/python3.8/site-packages/starlette/middleware/errors.py", line 162, in __call__
    await self.app(scope, receive, _send)
  File "/home/azureuser/DeepVoice-English-API/venv/lib/python3.8/site-packages/starlette/middleware/cors.py", line 83, in __call__
    await self.app(scope, receive, send)
  File "/home/azureuser/DeepVoice-English-API/venv/lib/python3.8/site-packages/starlette/middleware/exceptions.py", line 79, in __call__
    raise exc
  File "/home/azureuser/DeepVoice-English-API/venv/lib/python3.8/site-packages/starlette/middleware/exceptions.py", line 68, in __call__
    await self.app(scope, receive, sender)
  File "/home/azureuser/DeepVoice-English-API/venv/lib/python3.8/site-packages/fastapi/middleware/asyncexitstack.py", line 20, in __call__
    raise e
  File "/home/azureuser/DeepVoice-English-API/venv/lib/python3.8/site-packages/fastapi/middleware/asyncexitstack.py", line 17, in __call__
    await self.app(scope, receive, send)
  File "/home/azureuser/DeepVoice-English-API/venv/lib/python3.8/site-packages/starlette/routing.py", line 718, in __call__
    await route.handle(scope, receive, send)
  File "/home/azureuser/DeepVoice-English-API/venv/lib/python3.8/site-packages/starlette/routing.py", line 276, in handle
    await self.app(scope, receive, send)
  File "/home/azureuser/DeepVoice-English-API/venv/lib/python3.8/site-packages/starlette/routing.py", line 66, in app
    response = await func(request)
  File "/home/azureuser/DeepVoice-English-API/venv/lib/python3.8/site-packages/fastapi/routing.py", line 273, in app
    raw_response = await run_endpoint_function(
  File "/home/azureuser/DeepVoice-English-API/venv/lib/python3.8/site-packages/fastapi/routing.py", line 192, in run_endpoint_function
    return await run_in_threadpool(dependant.call, **values)
  File "/home/azureuser/DeepVoice-English-API/venv/lib/python3.8/site-packages/starlette/concurrency.py", line 41, in run_in_threadpool
    return await anyio.to_thread.run_sync(func, *args)
  File "/home/azureuser/DeepVoice-English-API/venv/lib/python3.8/site-packages/anyio/to_thread.py", line 33, in run_sync
    return await get_asynclib().run_sync_in_worker_thread(
  File "/home/azureuser/DeepVoice-English-API/venv/lib/python3.8/site-packages/anyio/_backends/_asyncio.py", line 877, in run_sync_in_worker_thread
    return await future
  File "/home/azureuser/DeepVoice-English-API/venv/lib/python3.8/site-packages/anyio/_backends/_asyncio.py", line 807, in run
    result = context.run(func, *args)
  File "/home/azureuser/DeepVoice-English-API/app/company/companyController.py", line 35, in get_company
    currentCompany = company.get(db=db, id=company_id)
  File "/home/azureuser/DeepVoice-English-API/app/baseController.py", line 27, in get
    return db.query(self.model).filter(self.model.id == id).first()
  File "/home/azureuser/DeepVoice-English-API/venv/lib/python3.8/site-packages/sqlalchemy/orm/query.py", line 2748, in first
    return self.limit(1)._iter().first()  # type: ignore
  File "/home/azureuser/DeepVoice-English-API/venv/lib/python3.8/site-packages/sqlalchemy/orm/query.py", line 2847, in _iter
    result: Union[ScalarResult[_T], Result[_T]] = self.session.execute(
  File "/home/azureuser/DeepVoice-English-API/venv/lib/python3.8/site-packages/sqlalchemy/orm/session.py", line 2306, in execute
    return self._execute_internal(
  File "/home/azureuser/DeepVoice-English-API/venv/lib/python3.8/site-packages/sqlalchemy/orm/session.py", line 2178, in _execute_internal
    conn = self._connection_for_bind(bind)
  File "/home/azureuser/DeepVoice-English-API/venv/lib/python3.8/site-packages/sqlalchemy/orm/session.py", line 2045, in _connection_for_bind
    return trans._connection_for_bind(engine, execution_options)
  File "<string>", line 2, in _connection_for_bind
  File "/home/azureuser/DeepVoice-English-API/venv/lib/python3.8/site-packages/sqlalchemy/orm/state_changes.py", line 139, in _go
    ret_value = fn(self, *arg, **kw)
  File "/home/azureuser/DeepVoice-English-API/venv/lib/python3.8/site-packages/sqlalchemy/orm/session.py", line 1143, in _connection_for_bind
    conn = bind.connect()
  File "/home/azureuser/DeepVoice-English-API/venv/lib/python3.8/site-packages/sqlalchemy/engine/base.py", line 3268, in connect
    return self._connection_cls(self)
  File "/home/azureuser/DeepVoice-English-API/venv/lib/python3.8/site-packages/sqlalchemy/engine/base.py", line 147, in __init__
    Connection._handle_dbapi_exception_noconnection(
  File "/home/azureuser/DeepVoice-English-API/venv/lib/python3.8/site-packages/sqlalchemy/engine/base.py", line 2430, in _handle_dbapi_exception_noconnection
    raise sqlalchemy_exception.with_traceback(exc_info[2]) from e
  File "/home/azureuser/DeepVoice-English-API/venv/lib/python3.8/site-packages/sqlalchemy/engine/base.py", line 145, in __init__
    self._dbapi_connection = engine.raw_connection()
  File "/home/azureuser/DeepVoice-English-API/venv/lib/python3.8/site-packages/sqlalchemy/engine/base.py", line 3292, in raw_connection
    return self.pool.connect()
  File "/home/azureuser/DeepVoice-English-API/venv/lib/python3.8/site-packages/sqlalchemy/pool/base.py", line 452, in connect
    return _ConnectionFairy._checkout(self)
  File "/home/azureuser/DeepVoice-English-API/venv/lib/python3.8/site-packages/sqlalchemy/pool/base.py", line 1269, in _checkout
    fairy = _ConnectionRecord.checkout(pool)
  File "/home/azureuser/DeepVoice-English-API/venv/lib/python3.8/site-packages/sqlalchemy/pool/base.py", line 716, in checkout
    rec = pool._do_get()
  File "/home/azureuser/DeepVoice-English-API/venv/lib/python3.8/site-packages/sqlalchemy/pool/impl.py", line 170, in _do_get
    self._dec_overflow()
  File "/home/azureuser/DeepVoice-English-API/venv/lib/python3.8/site-packages/sqlalchemy/util/langhelpers.py", line 146, in __exit__
    raise exc_value.with_traceback(exc_tb)
  File "/home/azureuser/DeepVoice-English-API/venv/lib/python3.8/site-packages/sqlalchemy/pool/impl.py", line 167, in _do_get
    return self._create_connection()
  File "/home/azureuser/DeepVoice-English-API/venv/lib/python3.8/site-packages/sqlalchemy/pool/base.py", line 393, in _create_connection
    return _ConnectionRecord(self)
  File "/home/azureuser/DeepVoice-English-API/venv/lib/python3.8/site-packages/sqlalchemy/pool/base.py", line 678, in __init__
    self.__connect()
  File "/home/azureuser/DeepVoice-English-API/venv/lib/python3.8/site-packages/sqlalchemy/pool/base.py", line 903, in __connect
    pool.logger.debug("Error on connect(): %s", e)
  File "/home/azureuser/DeepVoice-English-API/venv/lib/python3.8/site-packages/sqlalchemy/util/langhelpers.py", line 146, in __exit__
    raise exc_value.with_traceback(exc_tb)
  File "/home/azureuser/DeepVoice-English-API/venv/lib/python3.8/site-packages/sqlalchemy/pool/base.py", line 898, in __connect
    self.dbapi_connection = connection = pool._invoke_creator(self)
  File "/home/azureuser/DeepVoice-English-API/venv/lib/python3.8/site-packages/sqlalchemy/engine/create.py", line 637, in connect
    return dialect.connect(*cargs, **cparams)
  File "/home/azureuser/DeepVoice-English-API/venv/lib/python3.8/site-packages/sqlalchemy/engine/default.py", line 616, in connect
    return self.loaded_dbapi.connect(*cargs, **cparams)
  File "/home/azureuser/DeepVoice-English-API/venv/lib/python3.8/site-packages/psycopg2/__init__.py", line 122, in connect
    conn = _connect(dsn, connection_factory=connection_factory, **kwasync)
sqlalchemy.exc.OperationalError: (psycopg2.OperationalError) could not translate host name "none" to address: Temporary failure in name resolution

(Background on this error at: https://sqlalche.me/e/20/e3q8)
[2023-12-07 15:55:05 +0000] [35635] [INFO] Starting gunicorn 21.2.0
[2023-12-07 15:55:05 +0000] [35635] [ERROR] Connection in use: ('0.0.0.0', 8000)
[2023-12-07 15:55:05 +0000] [35635] [ERROR] Retrying in 1 second.
[2023-12-07 15:55:06 +0000] [35635] [ERROR] Connection in use: ('0.0.0.0', 8000)
[2023-12-07 15:55:06 +0000] [35635] [ERROR] Retrying in 1 second.
[2023-12-07 15:55:07 +0000] [35635] [ERROR] Connection in use: ('0.0.0.0', 8000)
[2023-12-07 15:55:07 +0000] [35635] [ERROR] Retrying in 1 second.
[2023-12-07 15:55:08 +0000] [35635] [ERROR] Connection in use: ('0.0.0.0', 8000)
[2023-12-07 15:55:08 +0000] [35635] [ERROR] Retrying in 1 second.
[2023-12-07 15:55:09 +0000] [35635] [ERROR] Connection in use: ('0.0.0.0', 8000)
[2023-12-07 15:55:09 +0000] [35635] [ERROR] Retrying in 1 second.
[2023-12-07 15:55:10 +0000] [35635] [ERROR] Can't connect to ('0.0.0.0', 8000)
[2023-12-07 15:56:38 +0000] [35657] [INFO] Starting gunicorn 21.2.0
[2023-12-07 15:56:38 +0000] [35657] [ERROR] Connection in use: ('127.0.0.1', 8000)
[2023-12-07 15:56:38 +0000] [35657] [ERROR] Retrying in 1 second.
[2023-12-07 15:56:39 +0000] [35657] [ERROR] Connection in use: ('127.0.0.1', 8000)
[2023-12-07 15:56:39 +0000] [35657] [ERROR] Retrying in 1 second.
[2023-12-07 15:56:40 +0000] [35657] [ERROR] Connection in use: ('127.0.0.1', 8000)
[2023-12-07 15:56:40 +0000] [35657] [ERROR] Retrying in 1 second.
[2023-12-07 15:56:41 +0000] [35657] [ERROR] Connection in use: ('127.0.0.1', 8000)
[2023-12-07 15:56:41 +0000] [35657] [ERROR] Retrying in 1 second.
[2023-12-07 15:56:42 +0000] [35657] [ERROR] Connection in use: ('127.0.0.1', 8000)
[2023-12-07 15:56:42 +0000] [35657] [ERROR] Retrying in 1 second.
[2023-12-07 15:56:43 +0000] [35657] [ERROR] Can't connect to ('127.0.0.1', 8000)
[2023-12-07 15:57:08 +0000] [12714] [ERROR] Exception in ASGI application
Traceback (most recent call last):
  File "/home/azureuser/DeepVoice-English-API/venv/lib/python3.8/site-packages/sqlalchemy/engine/base.py", line 145, in __init__
    self._dbapi_connection = engine.raw_connection()
  File "/home/azureuser/DeepVoice-English-API/venv/lib/python3.8/site-packages/sqlalchemy/engine/base.py", line 3292, in raw_connection
    return self.pool.connect()
  File "/home/azureuser/DeepVoice-English-API/venv/lib/python3.8/site-packages/sqlalchemy/pool/base.py", line 452, in connect
    return _ConnectionFairy._checkout(self)
  File "/home/azureuser/DeepVoice-English-API/venv/lib/python3.8/site-packages/sqlalchemy/pool/base.py", line 1269, in _checkout
    fairy = _ConnectionRecord.checkout(pool)
  File "/home/azureuser/DeepVoice-English-API/venv/lib/python3.8/site-packages/sqlalchemy/pool/base.py", line 716, in checkout
    rec = pool._do_get()
  File "/home/azureuser/DeepVoice-English-API/venv/lib/python3.8/site-packages/sqlalchemy/pool/impl.py", line 170, in _do_get
    self._dec_overflow()
  File "/home/azureuser/DeepVoice-English-API/venv/lib/python3.8/site-packages/sqlalchemy/util/langhelpers.py", line 146, in __exit__
    raise exc_value.with_traceback(exc_tb)
  File "/home/azureuser/DeepVoice-English-API/venv/lib/python3.8/site-packages/sqlalchemy/pool/impl.py", line 167, in _do_get
    return self._create_connection()
  File "/home/azureuser/DeepVoice-English-API/venv/lib/python3.8/site-packages/sqlalchemy/pool/base.py", line 393, in _create_connection
    return _ConnectionRecord(self)
  File "/home/azureuser/DeepVoice-English-API/venv/lib/python3.8/site-packages/sqlalchemy/pool/base.py", line 678, in __init__
    self.__connect()
  File "/home/azureuser/DeepVoice-English-API/venv/lib/python3.8/site-packages/sqlalchemy/pool/base.py", line 903, in __connect
    pool.logger.debug("Error on connect(): %s", e)
  File "/home/azureuser/DeepVoice-English-API/venv/lib/python3.8/site-packages/sqlalchemy/util/langhelpers.py", line 146, in __exit__
    raise exc_value.with_traceback(exc_tb)
  File "/home/azureuser/DeepVoice-English-API/venv/lib/python3.8/site-packages/sqlalchemy/pool/base.py", line 898, in __connect
    self.dbapi_connection = connection = pool._invoke_creator(self)
  File "/home/azureuser/DeepVoice-English-API/venv/lib/python3.8/site-packages/sqlalchemy/engine/create.py", line 637, in connect
    return dialect.connect(*cargs, **cparams)
  File "/home/azureuser/DeepVoice-English-API/venv/lib/python3.8/site-packages/sqlalchemy/engine/default.py", line 616, in connect
    return self.loaded_dbapi.connect(*cargs, **cparams)
  File "/home/azureuser/DeepVoice-English-API/venv/lib/python3.8/site-packages/psycopg2/__init__.py", line 122, in connect
    conn = _connect(dsn, connection_factory=connection_factory, **kwasync)
psycopg2.OperationalError: could not translate host name "none" to address: Temporary failure in name resolution


The above exception was the direct cause of the following exception:

Traceback (most recent call last):
  File "/home/azureuser/DeepVoice-English-API/venv/lib/python3.8/site-packages/uvicorn/protocols/http/httptools_impl.py", line 426, in run_asgi
    result = await app(  # type: ignore[func-returns-value]
  File "/home/azureuser/DeepVoice-English-API/venv/lib/python3.8/site-packages/uvicorn/middleware/proxy_headers.py", line 84, in __call__
    return await self.app(scope, receive, send)
  File "/home/azureuser/DeepVoice-English-API/venv/lib/python3.8/site-packages/fastapi/applications.py", line 292, in __call__
    await super().__call__(scope, receive, send)
  File "/home/azureuser/DeepVoice-English-API/venv/lib/python3.8/site-packages/starlette/applications.py", line 122, in __call__
    await self.middleware_stack(scope, receive, send)
  File "/home/azureuser/DeepVoice-English-API/venv/lib/python3.8/site-packages/starlette/middleware/errors.py", line 184, in __call__
    raise exc
  File "/home/azureuser/DeepVoice-English-API/venv/lib/python3.8/site-packages/starlette/middleware/errors.py", line 162, in __call__
    await self.app(scope, receive, _send)
  File "/home/azureuser/DeepVoice-English-API/venv/lib/python3.8/site-packages/starlette/middleware/cors.py", line 83, in __call__
    await self.app(scope, receive, send)
  File "/home/azureuser/DeepVoice-English-API/venv/lib/python3.8/site-packages/starlette/middleware/exceptions.py", line 79, in __call__
    raise exc
  File "/home/azureuser/DeepVoice-English-API/venv/lib/python3.8/site-packages/starlette/middleware/exceptions.py", line 68, in __call__
    await self.app(scope, receive, sender)
  File "/home/azureuser/DeepVoice-English-API/venv/lib/python3.8/site-packages/fastapi/middleware/asyncexitstack.py", line 20, in __call__
    raise e
  File "/home/azureuser/DeepVoice-English-API/venv/lib/python3.8/site-packages/fastapi/middleware/asyncexitstack.py", line 17, in __call__
    await self.app(scope, receive, send)
  File "/home/azureuser/DeepVoice-English-API/venv/lib/python3.8/site-packages/starlette/routing.py", line 718, in __call__
    await route.handle(scope, receive, send)
  File "/home/azureuser/DeepVoice-English-API/venv/lib/python3.8/site-packages/starlette/routing.py", line 276, in handle
    await self.app(scope, receive, send)
  File "/home/azureuser/DeepVoice-English-API/venv/lib/python3.8/site-packages/starlette/routing.py", line 66, in app
    response = await func(request)
  File "/home/azureuser/DeepVoice-English-API/venv/lib/python3.8/site-packages/fastapi/routing.py", line 273, in app
    raw_response = await run_endpoint_function(
  File "/home/azureuser/DeepVoice-English-API/venv/lib/python3.8/site-packages/fastapi/routing.py", line 192, in run_endpoint_function
    return await run_in_threadpool(dependant.call, **values)
  File "/home/azureuser/DeepVoice-English-API/venv/lib/python3.8/site-packages/starlette/concurrency.py", line 41, in run_in_threadpool
    return await anyio.to_thread.run_sync(func, *args)
  File "/home/azureuser/DeepVoice-English-API/venv/lib/python3.8/site-packages/anyio/to_thread.py", line 33, in run_sync
    return await get_asynclib().run_sync_in_worker_thread(
  File "/home/azureuser/DeepVoice-English-API/venv/lib/python3.8/site-packages/anyio/_backends/_asyncio.py", line 877, in run_sync_in_worker_thread
    return await future
  File "/home/azureuser/DeepVoice-English-API/venv/lib/python3.8/site-packages/anyio/_backends/_asyncio.py", line 807, in run
    result = context.run(func, *args)
  File "/home/azureuser/DeepVoice-English-API/app/company/companyController.py", line 35, in get_company
    currentCompany = company.get(db=db, id=company_id)
  File "/home/azureuser/DeepVoice-English-API/app/baseController.py", line 27, in get
    return db.query(self.model).filter(self.model.id == id).first()
  File "/home/azureuser/DeepVoice-English-API/venv/lib/python3.8/site-packages/sqlalchemy/orm/query.py", line 2748, in first
    return self.limit(1)._iter().first()  # type: ignore
  File "/home/azureuser/DeepVoice-English-API/venv/lib/python3.8/site-packages/sqlalchemy/orm/query.py", line 2847, in _iter
    result: Union[ScalarResult[_T], Result[_T]] = self.session.execute(
  File "/home/azureuser/DeepVoice-English-API/venv/lib/python3.8/site-packages/sqlalchemy/orm/session.py", line 2306, in execute
    return self._execute_internal(
  File "/home/azureuser/DeepVoice-English-API/venv/lib/python3.8/site-packages/sqlalchemy/orm/session.py", line 2178, in _execute_internal
    conn = self._connection_for_bind(bind)
  File "/home/azureuser/DeepVoice-English-API/venv/lib/python3.8/site-packages/sqlalchemy/orm/session.py", line 2045, in _connection_for_bind
    return trans._connection_for_bind(engine, execution_options)
  File "<string>", line 2, in _connection_for_bind
  File "/home/azureuser/DeepVoice-English-API/venv/lib/python3.8/site-packages/sqlalchemy/orm/state_changes.py", line 139, in _go
    ret_value = fn(self, *arg, **kw)
  File "/home/azureuser/DeepVoice-English-API/venv/lib/python3.8/site-packages/sqlalchemy/orm/session.py", line 1143, in _connection_for_bind
    conn = bind.connect()
  File "/home/azureuser/DeepVoice-English-API/venv/lib/python3.8/site-packages/sqlalchemy/engine/base.py", line 3268, in connect
    return self._connection_cls(self)
  File "/home/azureuser/DeepVoice-English-API/venv/lib/python3.8/site-packages/sqlalchemy/engine/base.py", line 147, in __init__
    Connection._handle_dbapi_exception_noconnection(
  File "/home/azureuser/DeepVoice-English-API/venv/lib/python3.8/site-packages/sqlalchemy/engine/base.py", line 2430, in _handle_dbapi_exception_noconnection
    raise sqlalchemy_exception.with_traceback(exc_info[2]) from e
  File "/home/azureuser/DeepVoice-English-API/venv/lib/python3.8/site-packages/sqlalchemy/engine/base.py", line 145, in __init__
    self._dbapi_connection = engine.raw_connection()
  File "/home/azureuser/DeepVoice-English-API/venv/lib/python3.8/site-packages/sqlalchemy/engine/base.py", line 3292, in raw_connection
    return self.pool.connect()
  File "/home/azureuser/DeepVoice-English-API/venv/lib/python3.8/site-packages/sqlalchemy/pool/base.py", line 452, in connect
    return _ConnectionFairy._checkout(self)
  File "/home/azureuser/DeepVoice-English-API/venv/lib/python3.8/site-packages/sqlalchemy/pool/base.py", line 1269, in _checkout
    fairy = _ConnectionRecord.checkout(pool)
  File "/home/azureuser/DeepVoice-English-API/venv/lib/python3.8/site-packages/sqlalchemy/pool/base.py", line 716, in checkout
    rec = pool._do_get()
  File "/home/azureuser/DeepVoice-English-API/venv/lib/python3.8/site-packages/sqlalchemy/pool/impl.py", line 170, in _do_get
    self._dec_overflow()
  File "/home/azureuser/DeepVoice-English-API/venv/lib/python3.8/site-packages/sqlalchemy/util/langhelpers.py", line 146, in __exit__
    raise exc_value.with_traceback(exc_tb)
  File "/home/azureuser/DeepVoice-English-API/venv/lib/python3.8/site-packages/sqlalchemy/pool/impl.py", line 167, in _do_get
    return self._create_connection()
  File "/home/azureuser/DeepVoice-English-API/venv/lib/python3.8/site-packages/sqlalchemy/pool/base.py", line 393, in _create_connection
    return _ConnectionRecord(self)
  File "/home/azureuser/DeepVoice-English-API/venv/lib/python3.8/site-packages/sqlalchemy/pool/base.py", line 678, in __init__
    self.__connect()
  File "/home/azureuser/DeepVoice-English-API/venv/lib/python3.8/site-packages/sqlalchemy/pool/base.py", line 903, in __connect
    pool.logger.debug("Error on connect(): %s", e)
  File "/home/azureuser/DeepVoice-English-API/venv/lib/python3.8/site-packages/sqlalchemy/util/langhelpers.py", line 146, in __exit__
    raise exc_value.with_traceback(exc_tb)
  File "/home/azureuser/DeepVoice-English-API/venv/lib/python3.8/site-packages/sqlalchemy/pool/base.py", line 898, in __connect
    self.dbapi_connection = connection = pool._invoke_creator(self)
  File "/home/azureuser/DeepVoice-English-API/venv/lib/python3.8/site-packages/sqlalchemy/engine/create.py", line 637, in connect
    return dialect.connect(*cargs, **cparams)
  File "/home/azureuser/DeepVoice-English-API/venv/lib/python3.8/site-packages/sqlalchemy/engine/default.py", line 616, in connect
    return self.loaded_dbapi.connect(*cargs, **cparams)
  File "/home/azureuser/DeepVoice-English-API/venv/lib/python3.8/site-packages/psycopg2/__init__.py", line 122, in connect
    conn = _connect(dsn, connection_factory=connection_factory, **kwasync)
sqlalchemy.exc.OperationalError: (psycopg2.OperationalError) could not translate host name "none" to address: Temporary failure in name resolution

(Background on this error at: https://sqlalche.me/e/20/e3q8)
[2023-12-07 16:01:27 +0000] [12714] [WARNING] Invalid HTTP request received.
[2023-12-07 16:04:44 +0000] [12716] [ERROR] Exception in ASGI application
Traceback (most recent call last):
  File "/home/azureuser/DeepVoice-English-API/venv/lib/python3.8/site-packages/sqlalchemy/engine/base.py", line 145, in __init__
    self._dbapi_connection = engine.raw_connection()
  File "/home/azureuser/DeepVoice-English-API/venv/lib/python3.8/site-packages/sqlalchemy/engine/base.py", line 3292, in raw_connection
    return self.pool.connect()
  File "/home/azureuser/DeepVoice-English-API/venv/lib/python3.8/site-packages/sqlalchemy/pool/base.py", line 452, in connect
    return _ConnectionFairy._checkout(self)
  File "/home/azureuser/DeepVoice-English-API/venv/lib/python3.8/site-packages/sqlalchemy/pool/base.py", line 1269, in _checkout
    fairy = _ConnectionRecord.checkout(pool)
  File "/home/azureuser/DeepVoice-English-API/venv/lib/python3.8/site-packages/sqlalchemy/pool/base.py", line 716, in checkout
    rec = pool._do_get()
  File "/home/azureuser/DeepVoice-English-API/venv/lib/python3.8/site-packages/sqlalchemy/pool/impl.py", line 170, in _do_get
    self._dec_overflow()
  File "/home/azureuser/DeepVoice-English-API/venv/lib/python3.8/site-packages/sqlalchemy/util/langhelpers.py", line 146, in __exit__
    raise exc_value.with_traceback(exc_tb)
  File "/home/azureuser/DeepVoice-English-API/venv/lib/python3.8/site-packages/sqlalchemy/pool/impl.py", line 167, in _do_get
    return self._create_connection()
  File "/home/azureuser/DeepVoice-English-API/venv/lib/python3.8/site-packages/sqlalchemy/pool/base.py", line 393, in _create_connection
    return _ConnectionRecord(self)
  File "/home/azureuser/DeepVoice-English-API/venv/lib/python3.8/site-packages/sqlalchemy/pool/base.py", line 678, in __init__
    self.__connect()
  File "/home/azureuser/DeepVoice-English-API/venv/lib/python3.8/site-packages/sqlalchemy/pool/base.py", line 903, in __connect
    pool.logger.debug("Error on connect(): %s", e)
  File "/home/azureuser/DeepVoice-English-API/venv/lib/python3.8/site-packages/sqlalchemy/util/langhelpers.py", line 146, in __exit__
    raise exc_value.with_traceback(exc_tb)
  File "/home/azureuser/DeepVoice-English-API/venv/lib/python3.8/site-packages/sqlalchemy/pool/base.py", line 898, in __connect
    self.dbapi_connection = connection = pool._invoke_creator(self)
  File "/home/azureuser/DeepVoice-English-API/venv/lib/python3.8/site-packages/sqlalchemy/engine/create.py", line 637, in connect
    return dialect.connect(*cargs, **cparams)
  File "/home/azureuser/DeepVoice-English-API/venv/lib/python3.8/site-packages/sqlalchemy/engine/default.py", line 616, in connect
    return self.loaded_dbapi.connect(*cargs, **cparams)
  File "/home/azureuser/DeepVoice-English-API/venv/lib/python3.8/site-packages/psycopg2/__init__.py", line 122, in connect
    conn = _connect(dsn, connection_factory=connection_factory, **kwasync)
psycopg2.OperationalError: could not translate host name "none" to address: Temporary failure in name resolution


The above exception was the direct cause of the following exception:

Traceback (most recent call last):
  File "/home/azureuser/DeepVoice-English-API/venv/lib/python3.8/site-packages/uvicorn/protocols/http/httptools_impl.py", line 426, in run_asgi
    result = await app(  # type: ignore[func-returns-value]
  File "/home/azureuser/DeepVoice-English-API/venv/lib/python3.8/site-packages/uvicorn/middleware/proxy_headers.py", line 84, in __call__
    return await self.app(scope, receive, send)
  File "/home/azureuser/DeepVoice-English-API/venv/lib/python3.8/site-packages/fastapi/applications.py", line 292, in __call__
    await super().__call__(scope, receive, send)
  File "/home/azureuser/DeepVoice-English-API/venv/lib/python3.8/site-packages/starlette/applications.py", line 122, in __call__
    await self.middleware_stack(scope, receive, send)
  File "/home/azureuser/DeepVoice-English-API/venv/lib/python3.8/site-packages/starlette/middleware/errors.py", line 184, in __call__
    raise exc
  File "/home/azureuser/DeepVoice-English-API/venv/lib/python3.8/site-packages/starlette/middleware/errors.py", line 162, in __call__
    await self.app(scope, receive, _send)
  File "/home/azureuser/DeepVoice-English-API/venv/lib/python3.8/site-packages/starlette/middleware/cors.py", line 83, in __call__
    await self.app(scope, receive, send)
  File "/home/azureuser/DeepVoice-English-API/venv/lib/python3.8/site-packages/starlette/middleware/exceptions.py", line 79, in __call__
    raise exc
  File "/home/azureuser/DeepVoice-English-API/venv/lib/python3.8/site-packages/starlette/middleware/exceptions.py", line 68, in __call__
    await self.app(scope, receive, sender)
  File "/home/azureuser/DeepVoice-English-API/venv/lib/python3.8/site-packages/fastapi/middleware/asyncexitstack.py", line 20, in __call__
    raise e
  File "/home/azureuser/DeepVoice-English-API/venv/lib/python3.8/site-packages/fastapi/middleware/asyncexitstack.py", line 17, in __call__
    await self.app(scope, receive, send)
  File "/home/azureuser/DeepVoice-English-API/venv/lib/python3.8/site-packages/starlette/routing.py", line 718, in __call__
    await route.handle(scope, receive, send)
  File "/home/azureuser/DeepVoice-English-API/venv/lib/python3.8/site-packages/starlette/routing.py", line 276, in handle
    await self.app(scope, receive, send)
  File "/home/azureuser/DeepVoice-English-API/venv/lib/python3.8/site-packages/starlette/routing.py", line 66, in app
    response = await func(request)
  File "/home/azureuser/DeepVoice-English-API/venv/lib/python3.8/site-packages/fastapi/routing.py", line 273, in app
    raw_response = await run_endpoint_function(
  File "/home/azureuser/DeepVoice-English-API/venv/lib/python3.8/site-packages/fastapi/routing.py", line 192, in run_endpoint_function
    return await run_in_threadpool(dependant.call, **values)
  File "/home/azureuser/DeepVoice-English-API/venv/lib/python3.8/site-packages/starlette/concurrency.py", line 41, in run_in_threadpool
    return await anyio.to_thread.run_sync(func, *args)
  File "/home/azureuser/DeepVoice-English-API/venv/lib/python3.8/site-packages/anyio/to_thread.py", line 33, in run_sync
    return await get_asynclib().run_sync_in_worker_thread(
  File "/home/azureuser/DeepVoice-English-API/venv/lib/python3.8/site-packages/anyio/_backends/_asyncio.py", line 877, in run_sync_in_worker_thread
    return await future
  File "/home/azureuser/DeepVoice-English-API/venv/lib/python3.8/site-packages/anyio/_backends/_asyncio.py", line 807, in run
    result = context.run(func, *args)
  File "/home/azureuser/DeepVoice-English-API/app/company/companyController.py", line 35, in get_company
    currentCompany = company.get(db=db, id=company_id)
  File "/home/azureuser/DeepVoice-English-API/app/baseController.py", line 27, in get
    return db.query(self.model).filter(self.model.id == id).first()
  File "/home/azureuser/DeepVoice-English-API/venv/lib/python3.8/site-packages/sqlalchemy/orm/query.py", line 2748, in first
    return self.limit(1)._iter().first()  # type: ignore
  File "/home/azureuser/DeepVoice-English-API/venv/lib/python3.8/site-packages/sqlalchemy/orm/query.py", line 2847, in _iter
    result: Union[ScalarResult[_T], Result[_T]] = self.session.execute(
  File "/home/azureuser/DeepVoice-English-API/venv/lib/python3.8/site-packages/sqlalchemy/orm/session.py", line 2306, in execute
    return self._execute_internal(
  File "/home/azureuser/DeepVoice-English-API/venv/lib/python3.8/site-packages/sqlalchemy/orm/session.py", line 2178, in _execute_internal
    conn = self._connection_for_bind(bind)
  File "/home/azureuser/DeepVoice-English-API/venv/lib/python3.8/site-packages/sqlalchemy/orm/session.py", line 2045, in _connection_for_bind
    return trans._connection_for_bind(engine, execution_options)
  File "<string>", line 2, in _connection_for_bind
  File "/home/azureuser/DeepVoice-English-API/venv/lib/python3.8/site-packages/sqlalchemy/orm/state_changes.py", line 139, in _go
    ret_value = fn(self, *arg, **kw)
  File "/home/azureuser/DeepVoice-English-API/venv/lib/python3.8/site-packages/sqlalchemy/orm/session.py", line 1143, in _connection_for_bind
    conn = bind.connect()
  File "/home/azureuser/DeepVoice-English-API/venv/lib/python3.8/site-packages/sqlalchemy/engine/base.py", line 3268, in connect
    return self._connection_cls(self)
  File "/home/azureuser/DeepVoice-English-API/venv/lib/python3.8/site-packages/sqlalchemy/engine/base.py", line 147, in __init__
    Connection._handle_dbapi_exception_noconnection(
  File "/home/azureuser/DeepVoice-English-API/venv/lib/python3.8/site-packages/sqlalchemy/engine/base.py", line 2430, in _handle_dbapi_exception_noconnection
    raise sqlalchemy_exception.with_traceback(exc_info[2]) from e
  File "/home/azureuser/DeepVoice-English-API/venv/lib/python3.8/site-packages/sqlalchemy/engine/base.py", line 145, in __init__
    self._dbapi_connection = engine.raw_connection()
  File "/home/azureuser/DeepVoice-English-API/venv/lib/python3.8/site-packages/sqlalchemy/engine/base.py", line 3292, in raw_connection
    return self.pool.connect()
  File "/home/azureuser/DeepVoice-English-API/venv/lib/python3.8/site-packages/sqlalchemy/pool/base.py", line 452, in connect
    return _ConnectionFairy._checkout(self)
  File "/home/azureuser/DeepVoice-English-API/venv/lib/python3.8/site-packages/sqlalchemy/pool/base.py", line 1269, in _checkout
    fairy = _ConnectionRecord.checkout(pool)
  File "/home/azureuser/DeepVoice-English-API/venv/lib/python3.8/site-packages/sqlalchemy/pool/base.py", line 716, in checkout
    rec = pool._do_get()
  File "/home/azureuser/DeepVoice-English-API/venv/lib/python3.8/site-packages/sqlalchemy/pool/impl.py", line 170, in _do_get
    self._dec_overflow()
  File "/home/azureuser/DeepVoice-English-API/venv/lib/python3.8/site-packages/sqlalchemy/util/langhelpers.py", line 146, in __exit__
    raise exc_value.with_traceback(exc_tb)
  File "/home/azureuser/DeepVoice-English-API/venv/lib/python3.8/site-packages/sqlalchemy/pool/impl.py", line 167, in _do_get
    return self._create_connection()
  File "/home/azureuser/DeepVoice-English-API/venv/lib/python3.8/site-packages/sqlalchemy/pool/base.py", line 393, in _create_connection
    return _ConnectionRecord(self)
  File "/home/azureuser/DeepVoice-English-API/venv/lib/python3.8/site-packages/sqlalchemy/pool/base.py", line 678, in __init__
    self.__connect()
  File "/home/azureuser/DeepVoice-English-API/venv/lib/python3.8/site-packages/sqlalchemy/pool/base.py", line 903, in __connect
    pool.logger.debug("Error on connect(): %s", e)
  File "/home/azureuser/DeepVoice-English-API/venv/lib/python3.8/site-packages/sqlalchemy/util/langhelpers.py", line 146, in __exit__
    raise exc_value.with_traceback(exc_tb)
  File "/home/azureuser/DeepVoice-English-API/venv/lib/python3.8/site-packages/sqlalchemy/pool/base.py", line 898, in __connect
    self.dbapi_connection = connection = pool._invoke_creator(self)
  File "/home/azureuser/DeepVoice-English-API/venv/lib/python3.8/site-packages/sqlalchemy/engine/create.py", line 637, in connect
    return dialect.connect(*cargs, **cparams)
  File "/home/azureuser/DeepVoice-English-API/venv/lib/python3.8/site-packages/sqlalchemy/engine/default.py", line 616, in connect
    return self.loaded_dbapi.connect(*cargs, **cparams)
  File "/home/azureuser/DeepVoice-English-API/venv/lib/python3.8/site-packages/psycopg2/__init__.py", line 122, in connect
    conn = _connect(dsn, connection_factory=connection_factory, **kwasync)
sqlalchemy.exc.OperationalError: (psycopg2.OperationalError) could not translate host name "none" to address: Temporary failure in name resolution

(Background on this error at: https://sqlalche.me/e/20/e3q8)
[2023-12-07 16:09:33 +0000] [12717] [ERROR] Exception in ASGI application
Traceback (most recent call last):
  File "/home/azureuser/DeepVoice-English-API/venv/lib/python3.8/site-packages/sqlalchemy/engine/base.py", line 145, in __init__
    self._dbapi_connection = engine.raw_connection()
  File "/home/azureuser/DeepVoice-English-API/venv/lib/python3.8/site-packages/sqlalchemy/engine/base.py", line 3292, in raw_connection
    return self.pool.connect()
  File "/home/azureuser/DeepVoice-English-API/venv/lib/python3.8/site-packages/sqlalchemy/pool/base.py", line 452, in connect
    return _ConnectionFairy._checkout(self)
  File "/home/azureuser/DeepVoice-English-API/venv/lib/python3.8/site-packages/sqlalchemy/pool/base.py", line 1269, in _checkout
    fairy = _ConnectionRecord.checkout(pool)
  File "/home/azureuser/DeepVoice-English-API/venv/lib/python3.8/site-packages/sqlalchemy/pool/base.py", line 716, in checkout
    rec = pool._do_get()
  File "/home/azureuser/DeepVoice-English-API/venv/lib/python3.8/site-packages/sqlalchemy/pool/impl.py", line 170, in _do_get
    self._dec_overflow()
  File "/home/azureuser/DeepVoice-English-API/venv/lib/python3.8/site-packages/sqlalchemy/util/langhelpers.py", line 146, in __exit__
    raise exc_value.with_traceback(exc_tb)
  File "/home/azureuser/DeepVoice-English-API/venv/lib/python3.8/site-packages/sqlalchemy/pool/impl.py", line 167, in _do_get
    return self._create_connection()
  File "/home/azureuser/DeepVoice-English-API/venv/lib/python3.8/site-packages/sqlalchemy/pool/base.py", line 393, in _create_connection
    return _ConnectionRecord(self)
  File "/home/azureuser/DeepVoice-English-API/venv/lib/python3.8/site-packages/sqlalchemy/pool/base.py", line 678, in __init__
    self.__connect()
  File "/home/azureuser/DeepVoice-English-API/venv/lib/python3.8/site-packages/sqlalchemy/pool/base.py", line 903, in __connect
    pool.logger.debug("Error on connect(): %s", e)
  File "/home/azureuser/DeepVoice-English-API/venv/lib/python3.8/site-packages/sqlalchemy/util/langhelpers.py", line 146, in __exit__
    raise exc_value.with_traceback(exc_tb)
  File "/home/azureuser/DeepVoice-English-API/venv/lib/python3.8/site-packages/sqlalchemy/pool/base.py", line 898, in __connect
    self.dbapi_connection = connection = pool._invoke_creator(self)
  File "/home/azureuser/DeepVoice-English-API/venv/lib/python3.8/site-packages/sqlalchemy/engine/create.py", line 637, in connect
    return dialect.connect(*cargs, **cparams)
  File "/home/azureuser/DeepVoice-English-API/venv/lib/python3.8/site-packages/sqlalchemy/engine/default.py", line 616, in connect
    return self.loaded_dbapi.connect(*cargs, **cparams)
  File "/home/azureuser/DeepVoice-English-API/venv/lib/python3.8/site-packages/psycopg2/__init__.py", line 122, in connect
    conn = _connect(dsn, connection_factory=connection_factory, **kwasync)
psycopg2.OperationalError: could not translate host name "none" to address: Temporary failure in name resolution


The above exception was the direct cause of the following exception:

Traceback (most recent call last):
  File "/home/azureuser/DeepVoice-English-API/venv/lib/python3.8/site-packages/uvicorn/protocols/http/httptools_impl.py", line 426, in run_asgi
    result = await app(  # type: ignore[func-returns-value]
  File "/home/azureuser/DeepVoice-English-API/venv/lib/python3.8/site-packages/uvicorn/middleware/proxy_headers.py", line 84, in __call__
    return await self.app(scope, receive, send)
  File "/home/azureuser/DeepVoice-English-API/venv/lib/python3.8/site-packages/fastapi/applications.py", line 292, in __call__
    await super().__call__(scope, receive, send)
  File "/home/azureuser/DeepVoice-English-API/venv/lib/python3.8/site-packages/starlette/applications.py", line 122, in __call__
    await self.middleware_stack(scope, receive, send)
  File "/home/azureuser/DeepVoice-English-API/venv/lib/python3.8/site-packages/starlette/middleware/errors.py", line 184, in __call__
    raise exc
  File "/home/azureuser/DeepVoice-English-API/venv/lib/python3.8/site-packages/starlette/middleware/errors.py", line 162, in __call__
    await self.app(scope, receive, _send)
  File "/home/azureuser/DeepVoice-English-API/venv/lib/python3.8/site-packages/starlette/middleware/cors.py", line 83, in __call__
    await self.app(scope, receive, send)
  File "/home/azureuser/DeepVoice-English-API/venv/lib/python3.8/site-packages/starlette/middleware/exceptions.py", line 79, in __call__
    raise exc
  File "/home/azureuser/DeepVoice-English-API/venv/lib/python3.8/site-packages/starlette/middleware/exceptions.py", line 68, in __call__
    await self.app(scope, receive, sender)
  File "/home/azureuser/DeepVoice-English-API/venv/lib/python3.8/site-packages/fastapi/middleware/asyncexitstack.py", line 20, in __call__
    raise e
  File "/home/azureuser/DeepVoice-English-API/venv/lib/python3.8/site-packages/fastapi/middleware/asyncexitstack.py", line 17, in __call__
    await self.app(scope, receive, send)
  File "/home/azureuser/DeepVoice-English-API/venv/lib/python3.8/site-packages/starlette/routing.py", line 718, in __call__
    await route.handle(scope, receive, send)
  File "/home/azureuser/DeepVoice-English-API/venv/lib/python3.8/site-packages/starlette/routing.py", line 276, in handle
    await self.app(scope, receive, send)
  File "/home/azureuser/DeepVoice-English-API/venv/lib/python3.8/site-packages/starlette/routing.py", line 66, in app
    response = await func(request)
  File "/home/azureuser/DeepVoice-English-API/venv/lib/python3.8/site-packages/fastapi/routing.py", line 273, in app
    raw_response = await run_endpoint_function(
  File "/home/azureuser/DeepVoice-English-API/venv/lib/python3.8/site-packages/fastapi/routing.py", line 192, in run_endpoint_function
    return await run_in_threadpool(dependant.call, **values)
  File "/home/azureuser/DeepVoice-English-API/venv/lib/python3.8/site-packages/starlette/concurrency.py", line 41, in run_in_threadpool
    return await anyio.to_thread.run_sync(func, *args)
  File "/home/azureuser/DeepVoice-English-API/venv/lib/python3.8/site-packages/anyio/to_thread.py", line 33, in run_sync
    return await get_asynclib().run_sync_in_worker_thread(
  File "/home/azureuser/DeepVoice-English-API/venv/lib/python3.8/site-packages/anyio/_backends/_asyncio.py", line 877, in run_sync_in_worker_thread
    return await future
  File "/home/azureuser/DeepVoice-English-API/venv/lib/python3.8/site-packages/anyio/_backends/_asyncio.py", line 807, in run
    result = context.run(func, *args)
  File "/home/azureuser/DeepVoice-English-API/app/company/companyController.py", line 35, in get_company
    currentCompany = company.get(db=db, id=company_id)
  File "/home/azureuser/DeepVoice-English-API/app/baseController.py", line 27, in get
    return db.query(self.model).filter(self.model.id == id).first()
  File "/home/azureuser/DeepVoice-English-API/venv/lib/python3.8/site-packages/sqlalchemy/orm/query.py", line 2748, in first
    return self.limit(1)._iter().first()  # type: ignore
  File "/home/azureuser/DeepVoice-English-API/venv/lib/python3.8/site-packages/sqlalchemy/orm/query.py", line 2847, in _iter
    result: Union[ScalarResult[_T], Result[_T]] = self.session.execute(
  File "/home/azureuser/DeepVoice-English-API/venv/lib/python3.8/site-packages/sqlalchemy/orm/session.py", line 2306, in execute
    return self._execute_internal(
  File "/home/azureuser/DeepVoice-English-API/venv/lib/python3.8/site-packages/sqlalchemy/orm/session.py", line 2178, in _execute_internal
    conn = self._connection_for_bind(bind)
  File "/home/azureuser/DeepVoice-English-API/venv/lib/python3.8/site-packages/sqlalchemy/orm/session.py", line 2045, in _connection_for_bind
    return trans._connection_for_bind(engine, execution_options)
  File "<string>", line 2, in _connection_for_bind
  File "/home/azureuser/DeepVoice-English-API/venv/lib/python3.8/site-packages/sqlalchemy/orm/state_changes.py", line 139, in _go
    ret_value = fn(self, *arg, **kw)
  File "/home/azureuser/DeepVoice-English-API/venv/lib/python3.8/site-packages/sqlalchemy/orm/session.py", line 1143, in _connection_for_bind
    conn = bind.connect()
  File "/home/azureuser/DeepVoice-English-API/venv/lib/python3.8/site-packages/sqlalchemy/engine/base.py", line 3268, in connect
    return self._connection_cls(self)
  File "/home/azureuser/DeepVoice-English-API/venv/lib/python3.8/site-packages/sqlalchemy/engine/base.py", line 147, in __init__
    Connection._handle_dbapi_exception_noconnection(
  File "/home/azureuser/DeepVoice-English-API/venv/lib/python3.8/site-packages/sqlalchemy/engine/base.py", line 2430, in _handle_dbapi_exception_noconnection
    raise sqlalchemy_exception.with_traceback(exc_info[2]) from e
  File "/home/azureuser/DeepVoice-English-API/venv/lib/python3.8/site-packages/sqlalchemy/engine/base.py", line 145, in __init__
    self._dbapi_connection = engine.raw_connection()
  File "/home/azureuser/DeepVoice-English-API/venv/lib/python3.8/site-packages/sqlalchemy/engine/base.py", line 3292, in raw_connection
    return self.pool.connect()
  File "/home/azureuser/DeepVoice-English-API/venv/lib/python3.8/site-packages/sqlalchemy/pool/base.py", line 452, in connect
    return _ConnectionFairy._checkout(self)
  File "/home/azureuser/DeepVoice-English-API/venv/lib/python3.8/site-packages/sqlalchemy/pool/base.py", line 1269, in _checkout
    fairy = _ConnectionRecord.checkout(pool)
  File "/home/azureuser/DeepVoice-English-API/venv/lib/python3.8/site-packages/sqlalchemy/pool/base.py", line 716, in checkout
    rec = pool._do_get()
  File "/home/azureuser/DeepVoice-English-API/venv/lib/python3.8/site-packages/sqlalchemy/pool/impl.py", line 170, in _do_get
    self._dec_overflow()
  File "/home/azureuser/DeepVoice-English-API/venv/lib/python3.8/site-packages/sqlalchemy/util/langhelpers.py", line 146, in __exit__
    raise exc_value.with_traceback(exc_tb)
  File "/home/azureuser/DeepVoice-English-API/venv/lib/python3.8/site-packages/sqlalchemy/pool/impl.py", line 167, in _do_get
    return self._create_connection()
  File "/home/azureuser/DeepVoice-English-API/venv/lib/python3.8/site-packages/sqlalchemy/pool/base.py", line 393, in _create_connection
    return _ConnectionRecord(self)
  File "/home/azureuser/DeepVoice-English-API/venv/lib/python3.8/site-packages/sqlalchemy/pool/base.py", line 678, in __init__
    self.__connect()
  File "/home/azureuser/DeepVoice-English-API/venv/lib/python3.8/site-packages/sqlalchemy/pool/base.py", line 903, in __connect
    pool.logger.debug("Error on connect(): %s", e)
  File "/home/azureuser/DeepVoice-English-API/venv/lib/python3.8/site-packages/sqlalchemy/util/langhelpers.py", line 146, in __exit__
    raise exc_value.with_traceback(exc_tb)
  File "/home/azureuser/DeepVoice-English-API/venv/lib/python3.8/site-packages/sqlalchemy/pool/base.py", line 898, in __connect
    self.dbapi_connection = connection = pool._invoke_creator(self)
  File "/home/azureuser/DeepVoice-English-API/venv/lib/python3.8/site-packages/sqlalchemy/engine/create.py", line 637, in connect
    return dialect.connect(*cargs, **cparams)
  File "/home/azureuser/DeepVoice-English-API/venv/lib/python3.8/site-packages/sqlalchemy/engine/default.py", line 616, in connect
    return self.loaded_dbapi.connect(*cargs, **cparams)
  File "/home/azureuser/DeepVoice-English-API/venv/lib/python3.8/site-packages/psycopg2/__init__.py", line 122, in connect
    conn = _connect(dsn, connection_factory=connection_factory, **kwasync)
sqlalchemy.exc.OperationalError: (psycopg2.OperationalError) could not translate host name "none" to address: Temporary failure in name resolution

(Background on this error at: https://sqlalche.me/e/20/e3q8)
[2023-12-07 16:13:34 +0000] [12717] [ERROR] Exception in ASGI application
Traceback (most recent call last):
  File "/home/azureuser/DeepVoice-English-API/venv/lib/python3.8/site-packages/sqlalchemy/engine/base.py", line 145, in __init__
    self._dbapi_connection = engine.raw_connection()
  File "/home/azureuser/DeepVoice-English-API/venv/lib/python3.8/site-packages/sqlalchemy/engine/base.py", line 3292, in raw_connection
    return self.pool.connect()
  File "/home/azureuser/DeepVoice-English-API/venv/lib/python3.8/site-packages/sqlalchemy/pool/base.py", line 452, in connect
    return _ConnectionFairy._checkout(self)
  File "/home/azureuser/DeepVoice-English-API/venv/lib/python3.8/site-packages/sqlalchemy/pool/base.py", line 1269, in _checkout
    fairy = _ConnectionRecord.checkout(pool)
  File "/home/azureuser/DeepVoice-English-API/venv/lib/python3.8/site-packages/sqlalchemy/pool/base.py", line 716, in checkout
    rec = pool._do_get()
  File "/home/azureuser/DeepVoice-English-API/venv/lib/python3.8/site-packages/sqlalchemy/pool/impl.py", line 170, in _do_get
    self._dec_overflow()
  File "/home/azureuser/DeepVoice-English-API/venv/lib/python3.8/site-packages/sqlalchemy/util/langhelpers.py", line 146, in __exit__
    raise exc_value.with_traceback(exc_tb)
  File "/home/azureuser/DeepVoice-English-API/venv/lib/python3.8/site-packages/sqlalchemy/pool/impl.py", line 167, in _do_get
    return self._create_connection()
  File "/home/azureuser/DeepVoice-English-API/venv/lib/python3.8/site-packages/sqlalchemy/pool/base.py", line 393, in _create_connection
    return _ConnectionRecord(self)
  File "/home/azureuser/DeepVoice-English-API/venv/lib/python3.8/site-packages/sqlalchemy/pool/base.py", line 678, in __init__
    self.__connect()
  File "/home/azureuser/DeepVoice-English-API/venv/lib/python3.8/site-packages/sqlalchemy/pool/base.py", line 903, in __connect
    pool.logger.debug("Error on connect(): %s", e)
  File "/home/azureuser/DeepVoice-English-API/venv/lib/python3.8/site-packages/sqlalchemy/util/langhelpers.py", line 146, in __exit__
    raise exc_value.with_traceback(exc_tb)
  File "/home/azureuser/DeepVoice-English-API/venv/lib/python3.8/site-packages/sqlalchemy/pool/base.py", line 898, in __connect
    self.dbapi_connection = connection = pool._invoke_creator(self)
  File "/home/azureuser/DeepVoice-English-API/venv/lib/python3.8/site-packages/sqlalchemy/engine/create.py", line 637, in connect
    return dialect.connect(*cargs, **cparams)
  File "/home/azureuser/DeepVoice-English-API/venv/lib/python3.8/site-packages/sqlalchemy/engine/default.py", line 616, in connect
    return self.loaded_dbapi.connect(*cargs, **cparams)
  File "/home/azureuser/DeepVoice-English-API/venv/lib/python3.8/site-packages/psycopg2/__init__.py", line 122, in connect
    conn = _connect(dsn, connection_factory=connection_factory, **kwasync)
psycopg2.OperationalError: could not translate host name "none" to address: Temporary failure in name resolution


The above exception was the direct cause of the following exception:

Traceback (most recent call last):
  File "/home/azureuser/DeepVoice-English-API/venv/lib/python3.8/site-packages/uvicorn/protocols/http/httptools_impl.py", line 426, in run_asgi
    result = await app(  # type: ignore[func-returns-value]
  File "/home/azureuser/DeepVoice-English-API/venv/lib/python3.8/site-packages/uvicorn/middleware/proxy_headers.py", line 84, in __call__
    return await self.app(scope, receive, send)
  File "/home/azureuser/DeepVoice-English-API/venv/lib/python3.8/site-packages/fastapi/applications.py", line 292, in __call__
    await super().__call__(scope, receive, send)
  File "/home/azureuser/DeepVoice-English-API/venv/lib/python3.8/site-packages/starlette/applications.py", line 122, in __call__
    await self.middleware_stack(scope, receive, send)
  File "/home/azureuser/DeepVoice-English-API/venv/lib/python3.8/site-packages/starlette/middleware/errors.py", line 184, in __call__
    raise exc
  File "/home/azureuser/DeepVoice-English-API/venv/lib/python3.8/site-packages/starlette/middleware/errors.py", line 162, in __call__
    await self.app(scope, receive, _send)
  File "/home/azureuser/DeepVoice-English-API/venv/lib/python3.8/site-packages/starlette/middleware/cors.py", line 83, in __call__
    await self.app(scope, receive, send)
  File "/home/azureuser/DeepVoice-English-API/venv/lib/python3.8/site-packages/starlette/middleware/exceptions.py", line 79, in __call__
    raise exc
  File "/home/azureuser/DeepVoice-English-API/venv/lib/python3.8/site-packages/starlette/middleware/exceptions.py", line 68, in __call__
    await self.app(scope, receive, sender)
  File "/home/azureuser/DeepVoice-English-API/venv/lib/python3.8/site-packages/fastapi/middleware/asyncexitstack.py", line 20, in __call__
    raise e
  File "/home/azureuser/DeepVoice-English-API/venv/lib/python3.8/site-packages/fastapi/middleware/asyncexitstack.py", line 17, in __call__
    await self.app(scope, receive, send)
  File "/home/azureuser/DeepVoice-English-API/venv/lib/python3.8/site-packages/starlette/routing.py", line 718, in __call__
    await route.handle(scope, receive, send)
  File "/home/azureuser/DeepVoice-English-API/venv/lib/python3.8/site-packages/starlette/routing.py", line 276, in handle
    await self.app(scope, receive, send)
  File "/home/azureuser/DeepVoice-English-API/venv/lib/python3.8/site-packages/starlette/routing.py", line 66, in app
    response = await func(request)
  File "/home/azureuser/DeepVoice-English-API/venv/lib/python3.8/site-packages/fastapi/routing.py", line 273, in app
    raw_response = await run_endpoint_function(
  File "/home/azureuser/DeepVoice-English-API/venv/lib/python3.8/site-packages/fastapi/routing.py", line 192, in run_endpoint_function
    return await run_in_threadpool(dependant.call, **values)
  File "/home/azureuser/DeepVoice-English-API/venv/lib/python3.8/site-packages/starlette/concurrency.py", line 41, in run_in_threadpool
    return await anyio.to_thread.run_sync(func, *args)
  File "/home/azureuser/DeepVoice-English-API/venv/lib/python3.8/site-packages/anyio/to_thread.py", line 33, in run_sync
    return await get_asynclib().run_sync_in_worker_thread(
  File "/home/azureuser/DeepVoice-English-API/venv/lib/python3.8/site-packages/anyio/_backends/_asyncio.py", line 877, in run_sync_in_worker_thread
    return await future
  File "/home/azureuser/DeepVoice-English-API/venv/lib/python3.8/site-packages/anyio/_backends/_asyncio.py", line 807, in run
    result = context.run(func, *args)
  File "/home/azureuser/DeepVoice-English-API/app/company/companyController.py", line 35, in get_company
    currentCompany = company.get(db=db, id=company_id)
  File "/home/azureuser/DeepVoice-English-API/app/baseController.py", line 27, in get
    return db.query(self.model).filter(self.model.id == id).first()
  File "/home/azureuser/DeepVoice-English-API/venv/lib/python3.8/site-packages/sqlalchemy/orm/query.py", line 2748, in first
    return self.limit(1)._iter().first()  # type: ignore
  File "/home/azureuser/DeepVoice-English-API/venv/lib/python3.8/site-packages/sqlalchemy/orm/query.py", line 2847, in _iter
    result: Union[ScalarResult[_T], Result[_T]] = self.session.execute(
  File "/home/azureuser/DeepVoice-English-API/venv/lib/python3.8/site-packages/sqlalchemy/orm/session.py", line 2306, in execute
    return self._execute_internal(
  File "/home/azureuser/DeepVoice-English-API/venv/lib/python3.8/site-packages/sqlalchemy/orm/session.py", line 2178, in _execute_internal
    conn = self._connection_for_bind(bind)
  File "/home/azureuser/DeepVoice-English-API/venv/lib/python3.8/site-packages/sqlalchemy/orm/session.py", line 2045, in _connection_for_bind
    return trans._connection_for_bind(engine, execution_options)
  File "<string>", line 2, in _connection_for_bind
  File "/home/azureuser/DeepVoice-English-API/venv/lib/python3.8/site-packages/sqlalchemy/orm/state_changes.py", line 139, in _go
    ret_value = fn(self, *arg, **kw)
  File "/home/azureuser/DeepVoice-English-API/venv/lib/python3.8/site-packages/sqlalchemy/orm/session.py", line 1143, in _connection_for_bind
    conn = bind.connect()
  File "/home/azureuser/DeepVoice-English-API/venv/lib/python3.8/site-packages/sqlalchemy/engine/base.py", line 3268, in connect
    return self._connection_cls(self)
  File "/home/azureuser/DeepVoice-English-API/venv/lib/python3.8/site-packages/sqlalchemy/engine/base.py", line 147, in __init__
    Connection._handle_dbapi_exception_noconnection(
  File "/home/azureuser/DeepVoice-English-API/venv/lib/python3.8/site-packages/sqlalchemy/engine/base.py", line 2430, in _handle_dbapi_exception_noconnection
    raise sqlalchemy_exception.with_traceback(exc_info[2]) from e
  File "/home/azureuser/DeepVoice-English-API/venv/lib/python3.8/site-packages/sqlalchemy/engine/base.py", line 145, in __init__
    self._dbapi_connection = engine.raw_connection()
  File "/home/azureuser/DeepVoice-English-API/venv/lib/python3.8/site-packages/sqlalchemy/engine/base.py", line 3292, in raw_connection
    return self.pool.connect()
  File "/home/azureuser/DeepVoice-English-API/venv/lib/python3.8/site-packages/sqlalchemy/pool/base.py", line 452, in connect
    return _ConnectionFairy._checkout(self)
  File "/home/azureuser/DeepVoice-English-API/venv/lib/python3.8/site-packages/sqlalchemy/pool/base.py", line 1269, in _checkout
    fairy = _ConnectionRecord.checkout(pool)
  File "/home/azureuser/DeepVoice-English-API/venv/lib/python3.8/site-packages/sqlalchemy/pool/base.py", line 716, in checkout
    rec = pool._do_get()
  File "/home/azureuser/DeepVoice-English-API/venv/lib/python3.8/site-packages/sqlalchemy/pool/impl.py", line 170, in _do_get
    self._dec_overflow()
  File "/home/azureuser/DeepVoice-English-API/venv/lib/python3.8/site-packages/sqlalchemy/util/langhelpers.py", line 146, in __exit__
    raise exc_value.with_traceback(exc_tb)
  File "/home/azureuser/DeepVoice-English-API/venv/lib/python3.8/site-packages/sqlalchemy/pool/impl.py", line 167, in _do_get
    return self._create_connection()
  File "/home/azureuser/DeepVoice-English-API/venv/lib/python3.8/site-packages/sqlalchemy/pool/base.py", line 393, in _create_connection
    return _ConnectionRecord(self)
  File "/home/azureuser/DeepVoice-English-API/venv/lib/python3.8/site-packages/sqlalchemy/pool/base.py", line 678, in __init__
    self.__connect()
  File "/home/azureuser/DeepVoice-English-API/venv/lib/python3.8/site-packages/sqlalchemy/pool/base.py", line 903, in __connect
    pool.logger.debug("Error on connect(): %s", e)
  File "/home/azureuser/DeepVoice-English-API/venv/lib/python3.8/site-packages/sqlalchemy/util/langhelpers.py", line 146, in __exit__
    raise exc_value.with_traceback(exc_tb)
  File "/home/azureuser/DeepVoice-English-API/venv/lib/python3.8/site-packages/sqlalchemy/pool/base.py", line 898, in __connect
    self.dbapi_connection = connection = pool._invoke_creator(self)
  File "/home/azureuser/DeepVoice-English-API/venv/lib/python3.8/site-packages/sqlalchemy/engine/create.py", line 637, in connect
    return dialect.connect(*cargs, **cparams)
  File "/home/azureuser/DeepVoice-English-API/venv/lib/python3.8/site-packages/sqlalchemy/engine/default.py", line 616, in connect
    return self.loaded_dbapi.connect(*cargs, **cparams)
  File "/home/azureuser/DeepVoice-English-API/venv/lib/python3.8/site-packages/psycopg2/__init__.py", line 122, in connect
    conn = _connect(dsn, connection_factory=connection_factory, **kwasync)
sqlalchemy.exc.OperationalError: (psycopg2.OperationalError) could not translate host name "none" to address: Temporary failure in name resolution

(Background on this error at: https://sqlalche.me/e/20/e3q8)
[2023-12-07 16:14:06 +0000] [35925] [INFO] Starting gunicorn 21.2.0
[2023-12-07 16:14:06 +0000] [35925] [ERROR] Connection in use: ('0.0.0.0', 8000)
[2023-12-07 16:14:06 +0000] [35925] [ERROR] Retrying in 1 second.
[2023-12-07 16:14:07 +0000] [35925] [ERROR] Connection in use: ('0.0.0.0', 8000)
[2023-12-07 16:14:07 +0000] [35925] [ERROR] Retrying in 1 second.
[2023-12-07 16:14:08 +0000] [35925] [ERROR] Connection in use: ('0.0.0.0', 8000)
[2023-12-07 16:14:08 +0000] [35925] [ERROR] Retrying in 1 second.
[2023-12-07 16:14:09 +0000] [35925] [ERROR] Connection in use: ('0.0.0.0', 8000)
[2023-12-07 16:14:09 +0000] [35925] [ERROR] Retrying in 1 second.
[2023-12-07 16:14:10 +0000] [35925] [ERROR] Connection in use: ('0.0.0.0', 8000)
[2023-12-07 16:14:10 +0000] [35925] [ERROR] Retrying in 1 second.
[2023-12-07 16:14:11 +0000] [35925] [ERROR] Can't connect to ('0.0.0.0', 8000)
[2023-12-07 16:14:33 +0000] [35941] [INFO] Starting gunicorn 21.2.0
[2023-12-07 16:14:33 +0000] [35941] [ERROR] Connection in use: ('0.0.0.0', 8000)
[2023-12-07 16:14:33 +0000] [35941] [ERROR] Retrying in 1 second.
[2023-12-07 16:14:34 +0000] [35941] [ERROR] Connection in use: ('0.0.0.0', 8000)
[2023-12-07 16:14:34 +0000] [35941] [ERROR] Retrying in 1 second.
[2023-12-07 16:14:35 +0000] [35941] [ERROR] Connection in use: ('0.0.0.0', 8000)
[2023-12-07 16:14:35 +0000] [35941] [ERROR] Retrying in 1 second.
[2023-12-07 16:14:36 +0000] [35941] [ERROR] Connection in use: ('0.0.0.0', 8000)
[2023-12-07 16:14:36 +0000] [35941] [ERROR] Retrying in 1 second.
[2023-12-07 16:14:37 +0000] [35941] [ERROR] Connection in use: ('0.0.0.0', 8000)
[2023-12-07 16:14:37 +0000] [35941] [ERROR] Retrying in 1 second.
[2023-12-07 16:14:38 +0000] [35941] [ERROR] Can't connect to ('0.0.0.0', 8000)
[2023-12-07 16:14:53 +0000] [12717] [ERROR] Exception in ASGI application
Traceback (most recent call last):
  File "/home/azureuser/DeepVoice-English-API/venv/lib/python3.8/site-packages/sqlalchemy/engine/base.py", line 145, in __init__
    self._dbapi_connection = engine.raw_connection()
  File "/home/azureuser/DeepVoice-English-API/venv/lib/python3.8/site-packages/sqlalchemy/engine/base.py", line 3292, in raw_connection
    return self.pool.connect()
  File "/home/azureuser/DeepVoice-English-API/venv/lib/python3.8/site-packages/sqlalchemy/pool/base.py", line 452, in connect
    return _ConnectionFairy._checkout(self)
  File "/home/azureuser/DeepVoice-English-API/venv/lib/python3.8/site-packages/sqlalchemy/pool/base.py", line 1269, in _checkout
    fairy = _ConnectionRecord.checkout(pool)
  File "/home/azureuser/DeepVoice-English-API/venv/lib/python3.8/site-packages/sqlalchemy/pool/base.py", line 716, in checkout
    rec = pool._do_get()
  File "/home/azureuser/DeepVoice-English-API/venv/lib/python3.8/site-packages/sqlalchemy/pool/impl.py", line 170, in _do_get
    self._dec_overflow()
  File "/home/azureuser/DeepVoice-English-API/venv/lib/python3.8/site-packages/sqlalchemy/util/langhelpers.py", line 146, in __exit__
    raise exc_value.with_traceback(exc_tb)
  File "/home/azureuser/DeepVoice-English-API/venv/lib/python3.8/site-packages/sqlalchemy/pool/impl.py", line 167, in _do_get
    return self._create_connection()
  File "/home/azureuser/DeepVoice-English-API/venv/lib/python3.8/site-packages/sqlalchemy/pool/base.py", line 393, in _create_connection
    return _ConnectionRecord(self)
  File "/home/azureuser/DeepVoice-English-API/venv/lib/python3.8/site-packages/sqlalchemy/pool/base.py", line 678, in __init__
    self.__connect()
  File "/home/azureuser/DeepVoice-English-API/venv/lib/python3.8/site-packages/sqlalchemy/pool/base.py", line 903, in __connect
    pool.logger.debug("Error on connect(): %s", e)
  File "/home/azureuser/DeepVoice-English-API/venv/lib/python3.8/site-packages/sqlalchemy/util/langhelpers.py", line 146, in __exit__
    raise exc_value.with_traceback(exc_tb)
  File "/home/azureuser/DeepVoice-English-API/venv/lib/python3.8/site-packages/sqlalchemy/pool/base.py", line 898, in __connect
    self.dbapi_connection = connection = pool._invoke_creator(self)
  File "/home/azureuser/DeepVoice-English-API/venv/lib/python3.8/site-packages/sqlalchemy/engine/create.py", line 637, in connect
    return dialect.connect(*cargs, **cparams)
  File "/home/azureuser/DeepVoice-English-API/venv/lib/python3.8/site-packages/sqlalchemy/engine/default.py", line 616, in connect
    return self.loaded_dbapi.connect(*cargs, **cparams)
  File "/home/azureuser/DeepVoice-English-API/venv/lib/python3.8/site-packages/psycopg2/__init__.py", line 122, in connect
    conn = _connect(dsn, connection_factory=connection_factory, **kwasync)
psycopg2.OperationalError: could not translate host name "none" to address: Temporary failure in name resolution


The above exception was the direct cause of the following exception:

Traceback (most recent call last):
  File "/home/azureuser/DeepVoice-English-API/venv/lib/python3.8/site-packages/uvicorn/protocols/http/httptools_impl.py", line 426, in run_asgi
    result = await app(  # type: ignore[func-returns-value]
  File "/home/azureuser/DeepVoice-English-API/venv/lib/python3.8/site-packages/uvicorn/middleware/proxy_headers.py", line 84, in __call__
    return await self.app(scope, receive, send)
  File "/home/azureuser/DeepVoice-English-API/venv/lib/python3.8/site-packages/fastapi/applications.py", line 292, in __call__
    await super().__call__(scope, receive, send)
  File "/home/azureuser/DeepVoice-English-API/venv/lib/python3.8/site-packages/starlette/applications.py", line 122, in __call__
    await self.middleware_stack(scope, receive, send)
  File "/home/azureuser/DeepVoice-English-API/venv/lib/python3.8/site-packages/starlette/middleware/errors.py", line 184, in __call__
    raise exc
  File "/home/azureuser/DeepVoice-English-API/venv/lib/python3.8/site-packages/starlette/middleware/errors.py", line 162, in __call__
    await self.app(scope, receive, _send)
  File "/home/azureuser/DeepVoice-English-API/venv/lib/python3.8/site-packages/starlette/middleware/cors.py", line 83, in __call__
    await self.app(scope, receive, send)
  File "/home/azureuser/DeepVoice-English-API/venv/lib/python3.8/site-packages/starlette/middleware/exceptions.py", line 79, in __call__
    raise exc
  File "/home/azureuser/DeepVoice-English-API/venv/lib/python3.8/site-packages/starlette/middleware/exceptions.py", line 68, in __call__
    await self.app(scope, receive, sender)
  File "/home/azureuser/DeepVoice-English-API/venv/lib/python3.8/site-packages/fastapi/middleware/asyncexitstack.py", line 20, in __call__
    raise e
  File "/home/azureuser/DeepVoice-English-API/venv/lib/python3.8/site-packages/fastapi/middleware/asyncexitstack.py", line 17, in __call__
    await self.app(scope, receive, send)
  File "/home/azureuser/DeepVoice-English-API/venv/lib/python3.8/site-packages/starlette/routing.py", line 718, in __call__
    await route.handle(scope, receive, send)
  File "/home/azureuser/DeepVoice-English-API/venv/lib/python3.8/site-packages/starlette/routing.py", line 276, in handle
    await self.app(scope, receive, send)
  File "/home/azureuser/DeepVoice-English-API/venv/lib/python3.8/site-packages/starlette/routing.py", line 66, in app
    response = await func(request)
  File "/home/azureuser/DeepVoice-English-API/venv/lib/python3.8/site-packages/fastapi/routing.py", line 273, in app
    raw_response = await run_endpoint_function(
  File "/home/azureuser/DeepVoice-English-API/venv/lib/python3.8/site-packages/fastapi/routing.py", line 192, in run_endpoint_function
    return await run_in_threadpool(dependant.call, **values)
  File "/home/azureuser/DeepVoice-English-API/venv/lib/python3.8/site-packages/starlette/concurrency.py", line 41, in run_in_threadpool
    return await anyio.to_thread.run_sync(func, *args)
  File "/home/azureuser/DeepVoice-English-API/venv/lib/python3.8/site-packages/anyio/to_thread.py", line 33, in run_sync
    return await get_asynclib().run_sync_in_worker_thread(
  File "/home/azureuser/DeepVoice-English-API/venv/lib/python3.8/site-packages/anyio/_backends/_asyncio.py", line 877, in run_sync_in_worker_thread
    return await future
  File "/home/azureuser/DeepVoice-English-API/venv/lib/python3.8/site-packages/anyio/_backends/_asyncio.py", line 807, in run
    result = context.run(func, *args)
  File "/home/azureuser/DeepVoice-English-API/app/company/companyController.py", line 35, in get_company
    currentCompany = company.get(db=db, id=company_id)
  File "/home/azureuser/DeepVoice-English-API/app/baseController.py", line 27, in get
    return db.query(self.model).filter(self.model.id == id).first()
  File "/home/azureuser/DeepVoice-English-API/venv/lib/python3.8/site-packages/sqlalchemy/orm/query.py", line 2748, in first
    return self.limit(1)._iter().first()  # type: ignore
  File "/home/azureuser/DeepVoice-English-API/venv/lib/python3.8/site-packages/sqlalchemy/orm/query.py", line 2847, in _iter
    result: Union[ScalarResult[_T], Result[_T]] = self.session.execute(
  File "/home/azureuser/DeepVoice-English-API/venv/lib/python3.8/site-packages/sqlalchemy/orm/session.py", line 2306, in execute
    return self._execute_internal(
  File "/home/azureuser/DeepVoice-English-API/venv/lib/python3.8/site-packages/sqlalchemy/orm/session.py", line 2178, in _execute_internal
    conn = self._connection_for_bind(bind)
  File "/home/azureuser/DeepVoice-English-API/venv/lib/python3.8/site-packages/sqlalchemy/orm/session.py", line 2045, in _connection_for_bind
    return trans._connection_for_bind(engine, execution_options)
  File "<string>", line 2, in _connection_for_bind
  File "/home/azureuser/DeepVoice-English-API/venv/lib/python3.8/site-packages/sqlalchemy/orm/state_changes.py", line 139, in _go
    ret_value = fn(self, *arg, **kw)
  File "/home/azureuser/DeepVoice-English-API/venv/lib/python3.8/site-packages/sqlalchemy/orm/session.py", line 1143, in _connection_for_bind
    conn = bind.connect()
  File "/home/azureuser/DeepVoice-English-API/venv/lib/python3.8/site-packages/sqlalchemy/engine/base.py", line 3268, in connect
    return self._connection_cls(self)
  File "/home/azureuser/DeepVoice-English-API/venv/lib/python3.8/site-packages/sqlalchemy/engine/base.py", line 147, in __init__
    Connection._handle_dbapi_exception_noconnection(
  File "/home/azureuser/DeepVoice-English-API/venv/lib/python3.8/site-packages/sqlalchemy/engine/base.py", line 2430, in _handle_dbapi_exception_noconnection
    raise sqlalchemy_exception.with_traceback(exc_info[2]) from e
  File "/home/azureuser/DeepVoice-English-API/venv/lib/python3.8/site-packages/sqlalchemy/engine/base.py", line 145, in __init__
    self._dbapi_connection = engine.raw_connection()
  File "/home/azureuser/DeepVoice-English-API/venv/lib/python3.8/site-packages/sqlalchemy/engine/base.py", line 3292, in raw_connection
    return self.pool.connect()
  File "/home/azureuser/DeepVoice-English-API/venv/lib/python3.8/site-packages/sqlalchemy/pool/base.py", line 452, in connect
    return _ConnectionFairy._checkout(self)
  File "/home/azureuser/DeepVoice-English-API/venv/lib/python3.8/site-packages/sqlalchemy/pool/base.py", line 1269, in _checkout
    fairy = _ConnectionRecord.checkout(pool)
  File "/home/azureuser/DeepVoice-English-API/venv/lib/python3.8/site-packages/sqlalchemy/pool/base.py", line 716, in checkout
    rec = pool._do_get()
  File "/home/azureuser/DeepVoice-English-API/venv/lib/python3.8/site-packages/sqlalchemy/pool/impl.py", line 170, in _do_get
    self._dec_overflow()
  File "/home/azureuser/DeepVoice-English-API/venv/lib/python3.8/site-packages/sqlalchemy/util/langhelpers.py", line 146, in __exit__
    raise exc_value.with_traceback(exc_tb)
  File "/home/azureuser/DeepVoice-English-API/venv/lib/python3.8/site-packages/sqlalchemy/pool/impl.py", line 167, in _do_get
    return self._create_connection()
  File "/home/azureuser/DeepVoice-English-API/venv/lib/python3.8/site-packages/sqlalchemy/pool/base.py", line 393, in _create_connection
    return _ConnectionRecord(self)
  File "/home/azureuser/DeepVoice-English-API/venv/lib/python3.8/site-packages/sqlalchemy/pool/base.py", line 678, in __init__
    self.__connect()
  File "/home/azureuser/DeepVoice-English-API/venv/lib/python3.8/site-packages/sqlalchemy/pool/base.py", line 903, in __connect
    pool.logger.debug("Error on connect(): %s", e)
  File "/home/azureuser/DeepVoice-English-API/venv/lib/python3.8/site-packages/sqlalchemy/util/langhelpers.py", line 146, in __exit__
    raise exc_value.with_traceback(exc_tb)
  File "/home/azureuser/DeepVoice-English-API/venv/lib/python3.8/site-packages/sqlalchemy/pool/base.py", line 898, in __connect
    self.dbapi_connection = connection = pool._invoke_creator(self)
  File "/home/azureuser/DeepVoice-English-API/venv/lib/python3.8/site-packages/sqlalchemy/engine/create.py", line 637, in connect
    return dialect.connect(*cargs, **cparams)
  File "/home/azureuser/DeepVoice-English-API/venv/lib/python3.8/site-packages/sqlalchemy/engine/default.py", line 616, in connect
    return self.loaded_dbapi.connect(*cargs, **cparams)
  File "/home/azureuser/DeepVoice-English-API/venv/lib/python3.8/site-packages/psycopg2/__init__.py", line 122, in connect
    conn = _connect(dsn, connection_factory=connection_factory, **kwasync)
sqlalchemy.exc.OperationalError: (psycopg2.OperationalError) could not translate host name "none" to address: Temporary failure in name resolution

(Background on this error at: https://sqlalche.me/e/20/e3q8)
[2023-12-07 16:16:28 +0000] [35968] [INFO] Starting gunicorn 21.2.0
[2023-12-07 16:16:28 +0000] [35968] [ERROR] Connection in use: ('0.0.0.0', 8000)
[2023-12-07 16:16:28 +0000] [35968] [ERROR] Retrying in 1 second.
[2023-12-07 16:16:29 +0000] [35968] [ERROR] Connection in use: ('0.0.0.0', 8000)
[2023-12-07 16:16:29 +0000] [35968] [ERROR] Retrying in 1 second.
[2023-12-07 16:16:30 +0000] [35968] [ERROR] Connection in use: ('0.0.0.0', 8000)
[2023-12-07 16:16:30 +0000] [35968] [ERROR] Retrying in 1 second.
[2023-12-07 16:16:31 +0000] [35968] [ERROR] Connection in use: ('0.0.0.0', 8000)
[2023-12-07 16:16:31 +0000] [35968] [ERROR] Retrying in 1 second.
[2023-12-07 16:16:32 +0000] [35968] [ERROR] Connection in use: ('0.0.0.0', 8000)
[2023-12-07 16:16:32 +0000] [35968] [ERROR] Retrying in 1 second.
[2023-12-07 16:16:33 +0000] [35968] [ERROR] Can't connect to ('0.0.0.0', 8000)
[2023-12-07 16:16:46 +0000] [12716] [ERROR] Exception in ASGI application
Traceback (most recent call last):
  File "/home/azureuser/DeepVoice-English-API/venv/lib/python3.8/site-packages/sqlalchemy/engine/base.py", line 145, in __init__
    self._dbapi_connection = engine.raw_connection()
  File "/home/azureuser/DeepVoice-English-API/venv/lib/python3.8/site-packages/sqlalchemy/engine/base.py", line 3292, in raw_connection
    return self.pool.connect()
  File "/home/azureuser/DeepVoice-English-API/venv/lib/python3.8/site-packages/sqlalchemy/pool/base.py", line 452, in connect
    return _ConnectionFairy._checkout(self)
  File "/home/azureuser/DeepVoice-English-API/venv/lib/python3.8/site-packages/sqlalchemy/pool/base.py", line 1269, in _checkout
    fairy = _ConnectionRecord.checkout(pool)
  File "/home/azureuser/DeepVoice-English-API/venv/lib/python3.8/site-packages/sqlalchemy/pool/base.py", line 716, in checkout
    rec = pool._do_get()
  File "/home/azureuser/DeepVoice-English-API/venv/lib/python3.8/site-packages/sqlalchemy/pool/impl.py", line 170, in _do_get
    self._dec_overflow()
  File "/home/azureuser/DeepVoice-English-API/venv/lib/python3.8/site-packages/sqlalchemy/util/langhelpers.py", line 146, in __exit__
    raise exc_value.with_traceback(exc_tb)
  File "/home/azureuser/DeepVoice-English-API/venv/lib/python3.8/site-packages/sqlalchemy/pool/impl.py", line 167, in _do_get
    return self._create_connection()
  File "/home/azureuser/DeepVoice-English-API/venv/lib/python3.8/site-packages/sqlalchemy/pool/base.py", line 393, in _create_connection
    return _ConnectionRecord(self)
  File "/home/azureuser/DeepVoice-English-API/venv/lib/python3.8/site-packages/sqlalchemy/pool/base.py", line 678, in __init__
    self.__connect()
  File "/home/azureuser/DeepVoice-English-API/venv/lib/python3.8/site-packages/sqlalchemy/pool/base.py", line 903, in __connect
    pool.logger.debug("Error on connect(): %s", e)
  File "/home/azureuser/DeepVoice-English-API/venv/lib/python3.8/site-packages/sqlalchemy/util/langhelpers.py", line 146, in __exit__
    raise exc_value.with_traceback(exc_tb)
  File "/home/azureuser/DeepVoice-English-API/venv/lib/python3.8/site-packages/sqlalchemy/pool/base.py", line 898, in __connect
    self.dbapi_connection = connection = pool._invoke_creator(self)
  File "/home/azureuser/DeepVoice-English-API/venv/lib/python3.8/site-packages/sqlalchemy/engine/create.py", line 637, in connect
    return dialect.connect(*cargs, **cparams)
  File "/home/azureuser/DeepVoice-English-API/venv/lib/python3.8/site-packages/sqlalchemy/engine/default.py", line 616, in connect
    return self.loaded_dbapi.connect(*cargs, **cparams)
  File "/home/azureuser/DeepVoice-English-API/venv/lib/python3.8/site-packages/psycopg2/__init__.py", line 122, in connect
    conn = _connect(dsn, connection_factory=connection_factory, **kwasync)
psycopg2.OperationalError: could not translate host name "none" to address: Temporary failure in name resolution


The above exception was the direct cause of the following exception:

Traceback (most recent call last):
  File "/home/azureuser/DeepVoice-English-API/venv/lib/python3.8/site-packages/uvicorn/protocols/http/httptools_impl.py", line 426, in run_asgi
    result = await app(  # type: ignore[func-returns-value]
  File "/home/azureuser/DeepVoice-English-API/venv/lib/python3.8/site-packages/uvicorn/middleware/proxy_headers.py", line 84, in __call__
    return await self.app(scope, receive, send)
  File "/home/azureuser/DeepVoice-English-API/venv/lib/python3.8/site-packages/fastapi/applications.py", line 292, in __call__
    await super().__call__(scope, receive, send)
  File "/home/azureuser/DeepVoice-English-API/venv/lib/python3.8/site-packages/starlette/applications.py", line 122, in __call__
    await self.middleware_stack(scope, receive, send)
  File "/home/azureuser/DeepVoice-English-API/venv/lib/python3.8/site-packages/starlette/middleware/errors.py", line 184, in __call__
    raise exc
  File "/home/azureuser/DeepVoice-English-API/venv/lib/python3.8/site-packages/starlette/middleware/errors.py", line 162, in __call__
    await self.app(scope, receive, _send)
  File "/home/azureuser/DeepVoice-English-API/venv/lib/python3.8/site-packages/starlette/middleware/cors.py", line 83, in __call__
    await self.app(scope, receive, send)
  File "/home/azureuser/DeepVoice-English-API/venv/lib/python3.8/site-packages/starlette/middleware/exceptions.py", line 79, in __call__
    raise exc
  File "/home/azureuser/DeepVoice-English-API/venv/lib/python3.8/site-packages/starlette/middleware/exceptions.py", line 68, in __call__
    await self.app(scope, receive, sender)
  File "/home/azureuser/DeepVoice-English-API/venv/lib/python3.8/site-packages/fastapi/middleware/asyncexitstack.py", line 20, in __call__
    raise e
  File "/home/azureuser/DeepVoice-English-API/venv/lib/python3.8/site-packages/fastapi/middleware/asyncexitstack.py", line 17, in __call__
    await self.app(scope, receive, send)
  File "/home/azureuser/DeepVoice-English-API/venv/lib/python3.8/site-packages/starlette/routing.py", line 718, in __call__
    await route.handle(scope, receive, send)
  File "/home/azureuser/DeepVoice-English-API/venv/lib/python3.8/site-packages/starlette/routing.py", line 276, in handle
    await self.app(scope, receive, send)
  File "/home/azureuser/DeepVoice-English-API/venv/lib/python3.8/site-packages/starlette/routing.py", line 66, in app
    response = await func(request)
  File "/home/azureuser/DeepVoice-English-API/venv/lib/python3.8/site-packages/fastapi/routing.py", line 273, in app
    raw_response = await run_endpoint_function(
  File "/home/azureuser/DeepVoice-English-API/venv/lib/python3.8/site-packages/fastapi/routing.py", line 192, in run_endpoint_function
    return await run_in_threadpool(dependant.call, **values)
  File "/home/azureuser/DeepVoice-English-API/venv/lib/python3.8/site-packages/starlette/concurrency.py", line 41, in run_in_threadpool
    return await anyio.to_thread.run_sync(func, *args)
  File "/home/azureuser/DeepVoice-English-API/venv/lib/python3.8/site-packages/anyio/to_thread.py", line 33, in run_sync
    return await get_asynclib().run_sync_in_worker_thread(
  File "/home/azureuser/DeepVoice-English-API/venv/lib/python3.8/site-packages/anyio/_backends/_asyncio.py", line 877, in run_sync_in_worker_thread
    return await future
  File "/home/azureuser/DeepVoice-English-API/venv/lib/python3.8/site-packages/anyio/_backends/_asyncio.py", line 807, in run
    result = context.run(func, *args)
  File "/home/azureuser/DeepVoice-English-API/app/company/companyController.py", line 35, in get_company
    currentCompany = company.get(db=db, id=company_id)
  File "/home/azureuser/DeepVoice-English-API/app/baseController.py", line 27, in get
    return db.query(self.model).filter(self.model.id == id).first()
  File "/home/azureuser/DeepVoice-English-API/venv/lib/python3.8/site-packages/sqlalchemy/orm/query.py", line 2748, in first
    return self.limit(1)._iter().first()  # type: ignore
  File "/home/azureuser/DeepVoice-English-API/venv/lib/python3.8/site-packages/sqlalchemy/orm/query.py", line 2847, in _iter
    result: Union[ScalarResult[_T], Result[_T]] = self.session.execute(
  File "/home/azureuser/DeepVoice-English-API/venv/lib/python3.8/site-packages/sqlalchemy/orm/session.py", line 2306, in execute
    return self._execute_internal(
  File "/home/azureuser/DeepVoice-English-API/venv/lib/python3.8/site-packages/sqlalchemy/orm/session.py", line 2178, in _execute_internal
    conn = self._connection_for_bind(bind)
  File "/home/azureuser/DeepVoice-English-API/venv/lib/python3.8/site-packages/sqlalchemy/orm/session.py", line 2045, in _connection_for_bind
    return trans._connection_for_bind(engine, execution_options)
  File "<string>", line 2, in _connection_for_bind
  File "/home/azureuser/DeepVoice-English-API/venv/lib/python3.8/site-packages/sqlalchemy/orm/state_changes.py", line 139, in _go
    ret_value = fn(self, *arg, **kw)
  File "/home/azureuser/DeepVoice-English-API/venv/lib/python3.8/site-packages/sqlalchemy/orm/session.py", line 1143, in _connection_for_bind
    conn = bind.connect()
  File "/home/azureuser/DeepVoice-English-API/venv/lib/python3.8/site-packages/sqlalchemy/engine/base.py", line 3268, in connect
    return self._connection_cls(self)
  File "/home/azureuser/DeepVoice-English-API/venv/lib/python3.8/site-packages/sqlalchemy/engine/base.py", line 147, in __init__
    Connection._handle_dbapi_exception_noconnection(
  File "/home/azureuser/DeepVoice-English-API/venv/lib/python3.8/site-packages/sqlalchemy/engine/base.py", line 2430, in _handle_dbapi_exception_noconnection
    raise sqlalchemy_exception.with_traceback(exc_info[2]) from e
  File "/home/azureuser/DeepVoice-English-API/venv/lib/python3.8/site-packages/sqlalchemy/engine/base.py", line 145, in __init__
    self._dbapi_connection = engine.raw_connection()
  File "/home/azureuser/DeepVoice-English-API/venv/lib/python3.8/site-packages/sqlalchemy/engine/base.py", line 3292, in raw_connection
    return self.pool.connect()
  File "/home/azureuser/DeepVoice-English-API/venv/lib/python3.8/site-packages/sqlalchemy/pool/base.py", line 452, in connect
    return _ConnectionFairy._checkout(self)
  File "/home/azureuser/DeepVoice-English-API/venv/lib/python3.8/site-packages/sqlalchemy/pool/base.py", line 1269, in _checkout
    fairy = _ConnectionRecord.checkout(pool)
  File "/home/azureuser/DeepVoice-English-API/venv/lib/python3.8/site-packages/sqlalchemy/pool/base.py", line 716, in checkout
    rec = pool._do_get()
  File "/home/azureuser/DeepVoice-English-API/venv/lib/python3.8/site-packages/sqlalchemy/pool/impl.py", line 170, in _do_get
    self._dec_overflow()
  File "/home/azureuser/DeepVoice-English-API/venv/lib/python3.8/site-packages/sqlalchemy/util/langhelpers.py", line 146, in __exit__
    raise exc_value.with_traceback(exc_tb)
  File "/home/azureuser/DeepVoice-English-API/venv/lib/python3.8/site-packages/sqlalchemy/pool/impl.py", line 167, in _do_get
    return self._create_connection()
  File "/home/azureuser/DeepVoice-English-API/venv/lib/python3.8/site-packages/sqlalchemy/pool/base.py", line 393, in _create_connection
    return _ConnectionRecord(self)
  File "/home/azureuser/DeepVoice-English-API/venv/lib/python3.8/site-packages/sqlalchemy/pool/base.py", line 678, in __init__
    self.__connect()
  File "/home/azureuser/DeepVoice-English-API/venv/lib/python3.8/site-packages/sqlalchemy/pool/base.py", line 903, in __connect
    pool.logger.debug("Error on connect(): %s", e)
  File "/home/azureuser/DeepVoice-English-API/venv/lib/python3.8/site-packages/sqlalchemy/util/langhelpers.py", line 146, in __exit__
    raise exc_value.with_traceback(exc_tb)
  File "/home/azureuser/DeepVoice-English-API/venv/lib/python3.8/site-packages/sqlalchemy/pool/base.py", line 898, in __connect
    self.dbapi_connection = connection = pool._invoke_creator(self)
  File "/home/azureuser/DeepVoice-English-API/venv/lib/python3.8/site-packages/sqlalchemy/engine/create.py", line 637, in connect
    return dialect.connect(*cargs, **cparams)
  File "/home/azureuser/DeepVoice-English-API/venv/lib/python3.8/site-packages/sqlalchemy/engine/default.py", line 616, in connect
    return self.loaded_dbapi.connect(*cargs, **cparams)
  File "/home/azureuser/DeepVoice-English-API/venv/lib/python3.8/site-packages/psycopg2/__init__.py", line 122, in connect
    conn = _connect(dsn, connection_factory=connection_factory, **kwasync)
sqlalchemy.exc.OperationalError: (psycopg2.OperationalError) could not translate host name "none" to address: Temporary failure in name resolution

(Background on this error at: https://sqlalche.me/e/20/e3q8)
[2023-12-07 16:26:28 +0000] [36056] [INFO] Starting gunicorn 21.2.0
[2023-12-07 16:26:28 +0000] [36056] [ERROR] Connection in use: ('0.0.0.0', 8000)
[2023-12-07 16:26:28 +0000] [36056] [ERROR] Retrying in 1 second.
[2023-12-07 16:26:29 +0000] [36056] [ERROR] Connection in use: ('0.0.0.0', 8000)
[2023-12-07 16:26:29 +0000] [36056] [ERROR] Retrying in 1 second.
[2023-12-07 16:26:30 +0000] [36056] [ERROR] Connection in use: ('0.0.0.0', 8000)
[2023-12-07 16:26:30 +0000] [36056] [ERROR] Retrying in 1 second.
[2023-12-07 16:26:31 +0000] [36056] [ERROR] Connection in use: ('0.0.0.0', 8000)
[2023-12-07 16:26:31 +0000] [36056] [ERROR] Retrying in 1 second.
[2023-12-07 16:26:32 +0000] [36056] [ERROR] Connection in use: ('0.0.0.0', 8000)
[2023-12-07 16:26:32 +0000] [36056] [ERROR] Retrying in 1 second.
[2023-12-07 16:26:33 +0000] [36056] [ERROR] Can't connect to ('0.0.0.0', 8000)
[2023-12-07 16:27:01 +0000] [12714] [ERROR] Exception in ASGI application
Traceback (most recent call last):
  File "/home/azureuser/DeepVoice-English-API/venv/lib/python3.8/site-packages/sqlalchemy/engine/base.py", line 145, in __init__
    self._dbapi_connection = engine.raw_connection()
  File "/home/azureuser/DeepVoice-English-API/venv/lib/python3.8/site-packages/sqlalchemy/engine/base.py", line 3292, in raw_connection
    return self.pool.connect()
  File "/home/azureuser/DeepVoice-English-API/venv/lib/python3.8/site-packages/sqlalchemy/pool/base.py", line 452, in connect
    return _ConnectionFairy._checkout(self)
  File "/home/azureuser/DeepVoice-English-API/venv/lib/python3.8/site-packages/sqlalchemy/pool/base.py", line 1269, in _checkout
    fairy = _ConnectionRecord.checkout(pool)
  File "/home/azureuser/DeepVoice-English-API/venv/lib/python3.8/site-packages/sqlalchemy/pool/base.py", line 716, in checkout
    rec = pool._do_get()
  File "/home/azureuser/DeepVoice-English-API/venv/lib/python3.8/site-packages/sqlalchemy/pool/impl.py", line 170, in _do_get
    self._dec_overflow()
  File "/home/azureuser/DeepVoice-English-API/venv/lib/python3.8/site-packages/sqlalchemy/util/langhelpers.py", line 146, in __exit__
    raise exc_value.with_traceback(exc_tb)
  File "/home/azureuser/DeepVoice-English-API/venv/lib/python3.8/site-packages/sqlalchemy/pool/impl.py", line 167, in _do_get
    return self._create_connection()
  File "/home/azureuser/DeepVoice-English-API/venv/lib/python3.8/site-packages/sqlalchemy/pool/base.py", line 393, in _create_connection
    return _ConnectionRecord(self)
  File "/home/azureuser/DeepVoice-English-API/venv/lib/python3.8/site-packages/sqlalchemy/pool/base.py", line 678, in __init__
    self.__connect()
  File "/home/azureuser/DeepVoice-English-API/venv/lib/python3.8/site-packages/sqlalchemy/pool/base.py", line 903, in __connect
    pool.logger.debug("Error on connect(): %s", e)
  File "/home/azureuser/DeepVoice-English-API/venv/lib/python3.8/site-packages/sqlalchemy/util/langhelpers.py", line 146, in __exit__
    raise exc_value.with_traceback(exc_tb)
  File "/home/azureuser/DeepVoice-English-API/venv/lib/python3.8/site-packages/sqlalchemy/pool/base.py", line 898, in __connect
    self.dbapi_connection = connection = pool._invoke_creator(self)
  File "/home/azureuser/DeepVoice-English-API/venv/lib/python3.8/site-packages/sqlalchemy/engine/create.py", line 637, in connect
    return dialect.connect(*cargs, **cparams)
  File "/home/azureuser/DeepVoice-English-API/venv/lib/python3.8/site-packages/sqlalchemy/engine/default.py", line 616, in connect
    return self.loaded_dbapi.connect(*cargs, **cparams)
  File "/home/azureuser/DeepVoice-English-API/venv/lib/python3.8/site-packages/psycopg2/__init__.py", line 122, in connect
    conn = _connect(dsn, connection_factory=connection_factory, **kwasync)
psycopg2.OperationalError: could not translate host name "none" to address: Temporary failure in name resolution


The above exception was the direct cause of the following exception:

Traceback (most recent call last):
  File "/home/azureuser/DeepVoice-English-API/venv/lib/python3.8/site-packages/uvicorn/protocols/http/httptools_impl.py", line 426, in run_asgi
    result = await app(  # type: ignore[func-returns-value]
  File "/home/azureuser/DeepVoice-English-API/venv/lib/python3.8/site-packages/uvicorn/middleware/proxy_headers.py", line 84, in __call__
    return await self.app(scope, receive, send)
  File "/home/azureuser/DeepVoice-English-API/venv/lib/python3.8/site-packages/fastapi/applications.py", line 292, in __call__
    await super().__call__(scope, receive, send)
  File "/home/azureuser/DeepVoice-English-API/venv/lib/python3.8/site-packages/starlette/applications.py", line 122, in __call__
    await self.middleware_stack(scope, receive, send)
  File "/home/azureuser/DeepVoice-English-API/venv/lib/python3.8/site-packages/starlette/middleware/errors.py", line 184, in __call__
    raise exc
  File "/home/azureuser/DeepVoice-English-API/venv/lib/python3.8/site-packages/starlette/middleware/errors.py", line 162, in __call__
    await self.app(scope, receive, _send)
  File "/home/azureuser/DeepVoice-English-API/venv/lib/python3.8/site-packages/starlette/middleware/cors.py", line 83, in __call__
    await self.app(scope, receive, send)
  File "/home/azureuser/DeepVoice-English-API/venv/lib/python3.8/site-packages/starlette/middleware/exceptions.py", line 79, in __call__
    raise exc
  File "/home/azureuser/DeepVoice-English-API/venv/lib/python3.8/site-packages/starlette/middleware/exceptions.py", line 68, in __call__
    await self.app(scope, receive, sender)
  File "/home/azureuser/DeepVoice-English-API/venv/lib/python3.8/site-packages/fastapi/middleware/asyncexitstack.py", line 20, in __call__
    raise e
  File "/home/azureuser/DeepVoice-English-API/venv/lib/python3.8/site-packages/fastapi/middleware/asyncexitstack.py", line 17, in __call__
    await self.app(scope, receive, send)
  File "/home/azureuser/DeepVoice-English-API/venv/lib/python3.8/site-packages/starlette/routing.py", line 718, in __call__
    await route.handle(scope, receive, send)
  File "/home/azureuser/DeepVoice-English-API/venv/lib/python3.8/site-packages/starlette/routing.py", line 276, in handle
    await self.app(scope, receive, send)
  File "/home/azureuser/DeepVoice-English-API/venv/lib/python3.8/site-packages/starlette/routing.py", line 66, in app
    response = await func(request)
  File "/home/azureuser/DeepVoice-English-API/venv/lib/python3.8/site-packages/fastapi/routing.py", line 273, in app
    raw_response = await run_endpoint_function(
  File "/home/azureuser/DeepVoice-English-API/venv/lib/python3.8/site-packages/fastapi/routing.py", line 192, in run_endpoint_function
    return await run_in_threadpool(dependant.call, **values)
  File "/home/azureuser/DeepVoice-English-API/venv/lib/python3.8/site-packages/starlette/concurrency.py", line 41, in run_in_threadpool
    return await anyio.to_thread.run_sync(func, *args)
  File "/home/azureuser/DeepVoice-English-API/venv/lib/python3.8/site-packages/anyio/to_thread.py", line 33, in run_sync
    return await get_asynclib().run_sync_in_worker_thread(
  File "/home/azureuser/DeepVoice-English-API/venv/lib/python3.8/site-packages/anyio/_backends/_asyncio.py", line 877, in run_sync_in_worker_thread
    return await future
  File "/home/azureuser/DeepVoice-English-API/venv/lib/python3.8/site-packages/anyio/_backends/_asyncio.py", line 807, in run
    result = context.run(func, *args)
  File "/home/azureuser/DeepVoice-English-API/app/company/companyController.py", line 35, in get_company
    currentCompany = company.get(db=db, id=company_id)
  File "/home/azureuser/DeepVoice-English-API/app/baseController.py", line 27, in get
    return db.query(self.model).filter(self.model.id == id).first()
  File "/home/azureuser/DeepVoice-English-API/venv/lib/python3.8/site-packages/sqlalchemy/orm/query.py", line 2748, in first
    return self.limit(1)._iter().first()  # type: ignore
  File "/home/azureuser/DeepVoice-English-API/venv/lib/python3.8/site-packages/sqlalchemy/orm/query.py", line 2847, in _iter
    result: Union[ScalarResult[_T], Result[_T]] = self.session.execute(
  File "/home/azureuser/DeepVoice-English-API/venv/lib/python3.8/site-packages/sqlalchemy/orm/session.py", line 2306, in execute
    return self._execute_internal(
  File "/home/azureuser/DeepVoice-English-API/venv/lib/python3.8/site-packages/sqlalchemy/orm/session.py", line 2178, in _execute_internal
    conn = self._connection_for_bind(bind)
  File "/home/azureuser/DeepVoice-English-API/venv/lib/python3.8/site-packages/sqlalchemy/orm/session.py", line 2045, in _connection_for_bind
    return trans._connection_for_bind(engine, execution_options)
  File "<string>", line 2, in _connection_for_bind
  File "/home/azureuser/DeepVoice-English-API/venv/lib/python3.8/site-packages/sqlalchemy/orm/state_changes.py", line 139, in _go
    ret_value = fn(self, *arg, **kw)
  File "/home/azureuser/DeepVoice-English-API/venv/lib/python3.8/site-packages/sqlalchemy/orm/session.py", line 1143, in _connection_for_bind
    conn = bind.connect()
  File "/home/azureuser/DeepVoice-English-API/venv/lib/python3.8/site-packages/sqlalchemy/engine/base.py", line 3268, in connect
    return self._connection_cls(self)
  File "/home/azureuser/DeepVoice-English-API/venv/lib/python3.8/site-packages/sqlalchemy/engine/base.py", line 147, in __init__
    Connection._handle_dbapi_exception_noconnection(
  File "/home/azureuser/DeepVoice-English-API/venv/lib/python3.8/site-packages/sqlalchemy/engine/base.py", line 2430, in _handle_dbapi_exception_noconnection
    raise sqlalchemy_exception.with_traceback(exc_info[2]) from e
  File "/home/azureuser/DeepVoice-English-API/venv/lib/python3.8/site-packages/sqlalchemy/engine/base.py", line 145, in __init__
    self._dbapi_connection = engine.raw_connection()
  File "/home/azureuser/DeepVoice-English-API/venv/lib/python3.8/site-packages/sqlalchemy/engine/base.py", line 3292, in raw_connection
    return self.pool.connect()
  File "/home/azureuser/DeepVoice-English-API/venv/lib/python3.8/site-packages/sqlalchemy/pool/base.py", line 452, in connect
    return _ConnectionFairy._checkout(self)
  File "/home/azureuser/DeepVoice-English-API/venv/lib/python3.8/site-packages/sqlalchemy/pool/base.py", line 1269, in _checkout
    fairy = _ConnectionRecord.checkout(pool)
  File "/home/azureuser/DeepVoice-English-API/venv/lib/python3.8/site-packages/sqlalchemy/pool/base.py", line 716, in checkout
    rec = pool._do_get()
  File "/home/azureuser/DeepVoice-English-API/venv/lib/python3.8/site-packages/sqlalchemy/pool/impl.py", line 170, in _do_get
    self._dec_overflow()
  File "/home/azureuser/DeepVoice-English-API/venv/lib/python3.8/site-packages/sqlalchemy/util/langhelpers.py", line 146, in __exit__
    raise exc_value.with_traceback(exc_tb)
  File "/home/azureuser/DeepVoice-English-API/venv/lib/python3.8/site-packages/sqlalchemy/pool/impl.py", line 167, in _do_get
    return self._create_connection()
  File "/home/azureuser/DeepVoice-English-API/venv/lib/python3.8/site-packages/sqlalchemy/pool/base.py", line 393, in _create_connection
    return _ConnectionRecord(self)
  File "/home/azureuser/DeepVoice-English-API/venv/lib/python3.8/site-packages/sqlalchemy/pool/base.py", line 678, in __init__
    self.__connect()
  File "/home/azureuser/DeepVoice-English-API/venv/lib/python3.8/site-packages/sqlalchemy/pool/base.py", line 903, in __connect
    pool.logger.debug("Error on connect(): %s", e)
  File "/home/azureuser/DeepVoice-English-API/venv/lib/python3.8/site-packages/sqlalchemy/util/langhelpers.py", line 146, in __exit__
    raise exc_value.with_traceback(exc_tb)
  File "/home/azureuser/DeepVoice-English-API/venv/lib/python3.8/site-packages/sqlalchemy/pool/base.py", line 898, in __connect
    self.dbapi_connection = connection = pool._invoke_creator(self)
  File "/home/azureuser/DeepVoice-English-API/venv/lib/python3.8/site-packages/sqlalchemy/engine/create.py", line 637, in connect
    return dialect.connect(*cargs, **cparams)
  File "/home/azureuser/DeepVoice-English-API/venv/lib/python3.8/site-packages/sqlalchemy/engine/default.py", line 616, in connect
    return self.loaded_dbapi.connect(*cargs, **cparams)
  File "/home/azureuser/DeepVoice-English-API/venv/lib/python3.8/site-packages/psycopg2/__init__.py", line 122, in connect
    conn = _connect(dsn, connection_factory=connection_factory, **kwasync)
sqlalchemy.exc.OperationalError: (psycopg2.OperationalError) could not translate host name "none" to address: Temporary failure in name resolution

(Background on this error at: https://sqlalche.me/e/20/e3q8)
[2023-12-07 21:38:41 +0000] [12717] [WARNING] Invalid HTTP request received.
[2023-12-07 21:50:22 +0000] [12714] [WARNING] Invalid HTTP request received.
[2023-12-08 01:45:28 +0000] [12715] [WARNING] Invalid HTTP request received.
[2023-12-08 01:45:28 +0000] [12716] [WARNING] Invalid HTTP request received.
[2023-12-08 01:45:28 +0000] [12714] [WARNING] Invalid HTTP request received.
[2023-12-08 01:45:29 +0000] [12716] [WARNING] Invalid HTTP request received.
[2023-12-08 01:45:29 +0000] [12716] [WARNING] Invalid HTTP request received.
[2023-12-08 01:45:29 +0000] [12717] [WARNING] Invalid HTTP request received.
[2023-12-08 01:45:29 +0000] [12716] [WARNING] Invalid HTTP request received.
[2023-12-08 01:45:29 +0000] [12717] [WARNING] Invalid HTTP request received.
[2023-12-08 01:45:29 +0000] [12717] [WARNING] Invalid HTTP request received.
[2023-12-08 06:09:18 +0000] [12717] [WARNING] Invalid HTTP request received.
[2023-12-08 06:19:02 +0000] [12715] [WARNING] Unsupported upgrade request.
[2023-12-08 06:19:02 +0000] [12715] [WARNING] No supported WebSocket library detected. Please use "pip install 'uvicorn[standard]'", or install 'websockets' or 'wsproto' manually.
[2023-12-08 06:19:02 +0000] [12715] [WARNING] Invalid HTTP request received.
[2023-12-08 07:43:41 +0000] [12716] [WARNING] Invalid HTTP request received.
[2023-12-08 07:43:41 +0000] [12717] [WARNING] Invalid HTTP request received.
[2023-12-08 08:35:02 +0000] [12715] [WARNING] Invalid HTTP request received.
[2023-12-08 11:29:26 +0000] [12715] [WARNING] Invalid HTTP request received.
[2023-12-08 14:04:55 +0000] [12715] [WARNING] Invalid HTTP request received.
[2023-12-08 14:29:13 +0000] [12715] [WARNING] Invalid HTTP request received.
[2023-12-08 14:29:14 +0000] [12716] [WARNING] Invalid HTTP request received.
[2023-12-08 14:29:15 +0000] [12716] [WARNING] Invalid HTTP request received.
[2023-12-08 14:33:20 +0000] [12717] [WARNING] Invalid HTTP request received.
[2023-12-08 14:34:11 +0000] [12717] [WARNING] Invalid HTTP request received.
[2023-12-08 20:59:29 +0000] [12714] [WARNING] Invalid HTTP request received.
[2023-12-09 00:00:35 +0000] [12716] [WARNING] Invalid HTTP request received.
[2023-12-09 00:00:35 +0000] [12716] [WARNING] Invalid HTTP request received.
[2023-12-09 01:52:56 +0000] [12716] [WARNING] Invalid HTTP request received.
[2023-12-09 01:52:56 +0000] [12716] [WARNING] Invalid HTTP request received.
[2023-12-09 01:52:56 +0000] [12715] [WARNING] Invalid HTTP request received.
[2023-12-09 01:52:57 +0000] [12714] [WARNING] Invalid HTTP request received.
[2023-12-09 01:52:57 +0000] [12714] [WARNING] Invalid HTTP request received.
[2023-12-09 01:52:57 +0000] [12714] [WARNING] Invalid HTTP request received.
[2023-12-09 01:52:57 +0000] [12716] [WARNING] Invalid HTTP request received.
[2023-12-09 01:52:57 +0000] [12715] [WARNING] Invalid HTTP request received.
[2023-12-09 01:52:57 +0000] [12716] [WARNING] Invalid HTTP request received.
[2023-12-09 02:26:29 +0000] [12717] [WARNING] Invalid HTTP request received.
[2023-12-09 02:50:11 +0000] [12715] [WARNING] Invalid HTTP request received.
[2023-12-09 08:24:03 +0000] [12715] [WARNING] Invalid HTTP request received.
[2023-12-09 08:52:57 +0000] [12715] [WARNING] Unsupported upgrade request.
[2023-12-09 08:52:57 +0000] [12715] [WARNING] No supported WebSocket library detected. Please use "pip install 'uvicorn[standard]'", or install 'websockets' or 'wsproto' manually.
[2023-12-09 08:52:57 +0000] [12715] [WARNING] Invalid HTTP request received.
[2023-12-09 09:35:58 +0000] [12714] [WARNING] Invalid HTTP request received.
[2023-12-09 12:35:20 +0000] [12715] [WARNING] Invalid HTTP request received.
[2023-12-09 13:56:47 +0000] [12715] [WARNING] Invalid HTTP request received.
[2023-12-09 15:15:24 +0000] [12714] [WARNING] Invalid HTTP request received.
[2023-12-09 21:48:31 +0000] [12715] [WARNING] Invalid HTTP request received.
[2023-12-09 23:20:32 +0000] [12716] [WARNING] Invalid HTTP request received.
[2023-12-09 23:20:32 +0000] [12715] [WARNING] Invalid HTTP request received.
[2023-12-09 23:20:33 +0000] [12717] [WARNING] Invalid HTTP request received.
[2023-12-09 23:32:59 +0000] [12715] [WARNING] Invalid HTTP request received.
[2023-12-10 02:02:15 +0000] [68417] [INFO] Starting gunicorn 21.2.0
[2023-12-10 02:02:15 +0000] [68417] [ERROR] Connection in use: ('0.0.0.0', 8000)
[2023-12-10 02:02:15 +0000] [68417] [ERROR] Retrying in 1 second.
[2023-12-10 02:02:16 +0000] [68417] [ERROR] Connection in use: ('0.0.0.0', 8000)
[2023-12-10 02:02:16 +0000] [68417] [ERROR] Retrying in 1 second.
[2023-12-10 02:02:17 +0000] [68417] [ERROR] Connection in use: ('0.0.0.0', 8000)
[2023-12-10 02:02:17 +0000] [68417] [ERROR] Retrying in 1 second.
[2023-12-10 02:02:18 +0000] [68417] [ERROR] Connection in use: ('0.0.0.0', 8000)
[2023-12-10 02:02:18 +0000] [68417] [ERROR] Retrying in 1 second.
[2023-12-10 02:02:19 +0000] [68417] [ERROR] Connection in use: ('0.0.0.0', 8000)
[2023-12-10 02:02:19 +0000] [68417] [ERROR] Retrying in 1 second.
[2023-12-10 02:02:20 +0000] [68417] [ERROR] Can't connect to ('0.0.0.0', 8000)
[2023-12-10 02:04:05 +0000] [12593] [INFO] Handling signal: hup
[2023-12-10 02:04:05 +0000] [12593] [INFO] Hang up: Master
[2023-12-10 02:04:05 +0000] [12593] [ERROR] Worker (pid:12714) was sent SIGHUP!
[2023-12-10 02:04:05 +0000] [12593] [ERROR] Worker (pid:12715) was sent SIGHUP!
[2023-12-10 02:04:05 +0000] [12593] [ERROR] Worker (pid:12716) was sent SIGHUP!
[2023-12-10 02:04:05 +0000] [12593] [ERROR] Worker (pid:12717) was sent SIGHUP!
[2023-12-10 02:04:05 +0000] [68470] [INFO] Booting worker with pid: 68470
[2023-12-10 02:04:05 +0000] [68472] [INFO] Booting worker with pid: 68472
[2023-12-10 02:04:05 +0000] [68473] [INFO] Booting worker with pid: 68473
[2023-12-10 02:04:05 +0000] [68475] [INFO] Booting worker with pid: 68475
[2023-12-10 02:04:05 +0000] [12593] [INFO] Handling signal: term
[2023-12-10 02:04:05 +0000] [12593] [ERROR] Worker (pid:68470) was sent SIGTERM!
[2023-12-10 02:04:05 +0000] [12593] [ERROR] Worker (pid:68472) was sent SIGTERM!
[2023-12-10 02:04:05 +0000] [12593] [ERROR] Worker (pid:68473) was sent SIGTERM!
[2023-12-10 02:04:06 +0000] [68475] [ERROR] Exception in worker process
Traceback (most recent call last):
  File "/home/azureuser/DeepVoice-English-API/venv/lib/python3.8/site-packages/gunicorn/arbiter.py", line 609, in spawn_worker
    worker.init_process()
  File "/home/azureuser/DeepVoice-English-API/venv/lib/python3.8/site-packages/uvicorn/workers.py", line 66, in init_process
    super(UvicornWorker, self).init_process()
  File "/home/azureuser/DeepVoice-English-API/venv/lib/python3.8/site-packages/gunicorn/workers/base.py", line 134, in init_process
    self.load_wsgi()
  File "/home/azureuser/DeepVoice-English-API/venv/lib/python3.8/site-packages/gunicorn/workers/base.py", line 146, in load_wsgi
    self.wsgi = self.app.wsgi()
  File "/home/azureuser/DeepVoice-English-API/venv/lib/python3.8/site-packages/gunicorn/app/base.py", line 67, in wsgi
    self.callable = self.load()
  File "/home/azureuser/DeepVoice-English-API/venv/lib/python3.8/site-packages/gunicorn/app/wsgiapp.py", line 58, in load
    return self.load_wsgiapp()
  File "/home/azureuser/DeepVoice-English-API/venv/lib/python3.8/site-packages/gunicorn/app/wsgiapp.py", line 48, in load_wsgiapp
    return util.import_app(self.app_uri)
  File "/home/azureuser/DeepVoice-English-API/venv/lib/python3.8/site-packages/gunicorn/util.py", line 371, in import_app
    mod = importlib.import_module(module)
  File "/usr/lib/python3.8/importlib/__init__.py", line 127, in import_module
    return _bootstrap._gcd_import(name[level:], package, level)
  File "<frozen importlib._bootstrap>", line 1014, in _gcd_import
  File "<frozen importlib._bootstrap>", line 991, in _find_and_load
  File "<frozen importlib._bootstrap>", line 975, in _find_and_load_unlocked
  File "<frozen importlib._bootstrap>", line 671, in _load_unlocked
  File "<frozen importlib._bootstrap_external>", line 848, in exec_module
  File "<frozen importlib._bootstrap>", line 219, in _call_with_frames_removed
  File "/home/azureuser/DeepVoice-English-API/app/main.py", line 4, in <module>
    from app.company.companyController import companyRouter
  File "/home/azureuser/DeepVoice-English-API/app/company/companyController.py", line 8, in <module>
    from app.company.companyService import company
  File "/home/azureuser/DeepVoice-English-API/app/company/companyService.py", line 5, in <module>
    from db import session
  File "/home/azureuser/DeepVoice-English-API/db/session.py", line 18, in <module>
    engine = create_engine(  # 2
  File "<string>", line 2, in create_engine
  File "/home/azureuser/DeepVoice-English-API/venv/lib/python3.8/site-packages/sqlalchemy/util/deprecations.py", line 281, in warned
    return fn(*args, **kwargs)  # type: ignore[no-any-return]
  File "/home/azureuser/DeepVoice-English-API/venv/lib/python3.8/site-packages/sqlalchemy/engine/create.py", line 548, in create_engine
    u = _url.make_url(url)
  File "/home/azureuser/DeepVoice-English-API/venv/lib/python3.8/site-packages/sqlalchemy/engine/url.py", line 838, in make_url
    return _parse_url(name_or_url)
  File "/home/azureuser/DeepVoice-English-API/venv/lib/python3.8/site-packages/sqlalchemy/engine/url.py", line 899, in _parse_url
    components["port"] = int(components["port"])
ValueError: invalid literal for int() with base 10: 'none'
[2023-12-10 02:04:06 +0000] [68475] [INFO] Worker exiting (pid: 68475)
USER-TEST None
[2023-12-10 02:04:06 +0000] [12593] [ERROR] Worker (pid:68475) exited with code 3
Traceback (most recent call last):
  File "/home/azureuser/DeepVoice-English-API/venv/lib/python3.8/site-packages/gunicorn/arbiter.py", line 224, in run
    handler()
  File "/home/azureuser/DeepVoice-English-API/venv/lib/python3.8/site-packages/gunicorn/arbiter.py", line 257, in handle_term
    raise StopIteration
StopIteration

During handling of the above exception, another exception occurred:

Traceback (most recent call last):
  File "/home/azureuser/DeepVoice-English-API/venv/bin/gunicorn", line 8, in <module>
    sys.exit(run())
  File "/home/azureuser/DeepVoice-English-API/venv/lib/python3.8/site-packages/gunicorn/app/wsgiapp.py", line 67, in run
    WSGIApplication("%(prog)s [OPTIONS] [APP_MODULE]").run()
  File "/home/azureuser/DeepVoice-English-API/venv/lib/python3.8/site-packages/gunicorn/app/base.py", line 236, in run
    super().run()
  File "/home/azureuser/DeepVoice-English-API/venv/lib/python3.8/site-packages/gunicorn/app/base.py", line 72, in run
    Arbiter(self).run()
  File "/home/azureuser/DeepVoice-English-API/venv/lib/python3.8/site-packages/gunicorn/arbiter.py", line 227, in run
    self.halt()
  File "/home/azureuser/DeepVoice-English-API/venv/lib/python3.8/site-packages/gunicorn/arbiter.py", line 342, in halt
    self.stop()
  File "/home/azureuser/DeepVoice-English-API/venv/lib/python3.8/site-packages/gunicorn/arbiter.py", line 396, in stop
    time.sleep(0.1)
  File "/home/azureuser/DeepVoice-English-API/venv/lib/python3.8/site-packages/gunicorn/arbiter.py", line 242, in handle_chld
    self.reap_workers()
  File "/home/azureuser/DeepVoice-English-API/venv/lib/python3.8/site-packages/gunicorn/arbiter.py", line 530, in reap_workers
    raise HaltServer(reason, self.WORKER_BOOT_ERROR)
gunicorn.errors.HaltServer: <HaltServer 'Worker failed to boot.' 3>
